Workbook

Sheet Read me
A1: Prenatal nitrate exposure and birth outcomes: study-level multipliers and pooled estimates
A2: Companion to the cancer workbook. Compiled 2026-10-20.
A4: The headline
A5: For very preterm birth, three independent analyses agree almost exactly. Semprini gives 1.46 in Iowa, Sherris gives 1.47 in California, and Stayner gives 1.47 across four Midwestern states once rescaled to the same contrast. Pooled: 1.47 (1.32 to 1.64) with I-squared of 0%. For preterm birth overall the three-study pool is 1.11 (1.06 to 1.16), also with zero heterogeneity.
A6: Zero heterogeneity across three designs and three populations is the thing to notice. Across the 20 cancer sites in the companion workbook, heterogeneity ran from 50% to 87%. This literature is behaving in a way the cancer literature does not.
A8: Sheets
A9: Study multipliers - every estimate from all four sources, grouped by outcome, with pooled rows. Columns U to AB hold the meta-analysis working.
A10: Pooled comparisons - the six study sets you asked for, per outcome: the three studies together, the SR alone, each of the three against the SR, and everything combined.
A11: Three-study pool - Semprini, Montoya and Sherris side by side, with the judgement calls stated.
A12: Scale and overlap - what the rescaling assumption does to each per-unit estimate, and the Sherris double-counting demonstration.
A13: Birth weight (grams) - continuous results, which have no multiplier form.
A15: Sources
... A32: All four sources are observational. Nothing here establishes causation, and the same latency and confounding caveats that apply to the cancer literature apply in weaker form here. What is different is that the exposure window is short and knowable, which is why the estimates agree with each other at all.

Sheet Study multipliers
A1: Outcome | B1: Study | C1: Year | D1: Role | E1: Design | F1: Country | G1: N | H1: Exposure contrast | I1: Native metric | J1: Multiplier | K1: 95% LCL | L1: 95% UCL | M1: Scale | N1: Mult. at 5 mg/L-N | O1: ln(mult5) | P1: SE(mult5) | Q1: Inv-var wt | R1: In pool | S1: RE weight | T1: Notes | U1: k | V1: FE | W1: Q | X1: C | Y1: tau^2 | Z1: I^2 | AA1: mu | AB1: SE(mu)
A2: Preterm <37wk
A3: Preterm <37wk | B3: Semprini | C3: 2026 | D3: Primary study | E3: Cohort (LPM, county FE) | F3: USA (Iowa) | G3: 113328 | H3: >=5 vs <=0.1 mg/L N | I3: RR from +1.036pp / 7.70% base | J3: 1.1346 | K3: 1.0317 | L3: 1.2374 | M3: cat5 | N3: =EXP(LN(J3)*1) -> 1.1346 | O3: =LN(J3)*1 -> 0.12628017 | P3: =((LN(L3)-LN(K3))/(2*1.959964))*1 -> 0.046379545 | Q3: =IF(P3>0,1/P3^2,0) -> 464.88661 | R3: 1 | S3: =IF(AND(R3=1,P3>0),1/(P3^2+$Y$13),0) -> 382.23701 | T3: Table 2; Sidak-adjusted CI 0.132-1.940pp also significant
A4: Preterm <37wk | B4: Semprini | C4: 2026 | D4: Primary study | E4: Cohort (LPM, county FE) | F4: USA (Iowa) | G4: 113328 | H4: >0.1 to <5 vs <=0.1 mg/L N | I4: RR from +0.275pp / 7.70% base | J4: 1.0357 | K4: 0.9547 | L4: 1.1167 | M4: sub5 | R4: 0 | S4: =IF(AND(R4=1,P4>0),1/(P4^2+$Y$13),0) -> 0 | T4: Intermediate category - null
A5: Preterm <37wk | B5: Montoya | C5: 2025 | D5: Primary study | E5: Cohort (IV, water-system FE) | F5: USA (California) | G5: 338962 | H5: Any month 5-10 vs <5 mg/L N, trimester 2 | I5: RR from +0.012 / 0.08 mean | J5: 1.15 | K5: 1.052 | L5: 1.248 | M5: cat5 | N5: =EXP(LN(J5)*1) -> 1.15 | O5: =LN(J5)*1 -> 0.13976194 | P5: =((LN(L5)-LN(K5))/(2*1.959964))*1 -> 0.043584769 | Q5: =IF(P5>0,1/P5^2,0) -> 526.41773 | R5: 1 | S5: =IF(AND(R5=1,P5>0),1/(P5^2+$Y$13),0) -> 422.87809 | T5: Table 2 Panel B, full-gestation IV (preferred)
A6: Preterm <37wk | B6: Montoya | C6: 2025 | D6: Primary study | E6: Cohort (no IV) | F6: USA (California) | G6: 338962 | H6: Any month 5-10 vs <5 mg/L N, trimester 2 | I6: RR from +0.020 / 0.08 mean | J6: 1.25 | K6: 1.1275 | L6: 1.3725 | M6: alt | R6: 0 | S6: =IF(AND(R6=1,P6>0),1/(P6^2+$Y$13),0) -> 0 | T6: Non-instrumented specification
A7: Preterm <37wk | B7: Montoya | C7: 2025 | D7: Primary study | E7: Cohort (IV, water-system FE) | F7: USA (California) | G7: 338962 | H7: Trimester 1 exposure 5-10 vs <5 mg/L N | I7: RR from -0.006 / 0.08 mean | J7: 0.925 | K7: 0.876 | L7: 0.974 | M7: alt | R7: 0 | S7: =IF(AND(R7=1,P7>0),1/(P7^2+$Y$13),0) -> 0 | T7: Trimester 1 - inverse
A8: Preterm <37wk | B8: Sherris | C8: 2021 | D8: Primary study + in SR | E8: Cohort, within-mother | F8: USA (California) | G8: 1443318 | H8: 5 to <10 vs <5 mg/L N (32-36wk) | I8: OR | J8: 1.08 | K8: 1.02 | L8: 1.15 | M8: cat5 | N8: =EXP(LN(J8)*1) -> 1.08 | O8: =LN(J8)*1 -> 0.076961041 | P8: =((LN(L8)-LN(K8))/(2*1.959964))*1 -> 0.030602428 | Q8: =IF(P8>0,1/P8^2,0) -> 1067.7958 | R8: 1 | S8: =IF(AND(R8=1,P8>0),1/(P8^2+$Y$13),0) -> 713.45796 | T8: 32-36wk spontaneous PTB. NOT all <37wk - see caveat
A9: Preterm <37wk | B9: Sherris | C9: 2021 | D9: Primary study + in SR | E9: Cohort, within-mother | F9: USA (California) | G9: 1443318 | H9: >=10 vs <5 mg/L N (32-36wk) | I9: OR | J9: 1.05 | K9: 0.85 | L9: 1.31 | M9: high | R9: 0 | S9: =IF(AND(R9=1,P9>0),1/(P9^2+$Y$13),0) -> 0 | T9: Above the MCL
A10: Preterm <37wk | B10: Huang | C10: 2018 | D10: In SR (Clemmensen 2023) | E10: Cohort | F10: USA (California) | G10: 1448600 | H10: Per 9.33 ppm nitrate (IQR) | I10: OR per 9.33 ppm | J10: 1.02 | K10: 1.01 | L10: 1.03 | M10: perunit | N10: =EXP(LN(J10)*2.37281700835232) -> 1.0481094 | O10: =LN(J10)*2.37281700835232 -> 0.046988011 | P10: =((LN(L10)-LN(K10))/(2*1.959964))*2.37281700835232 -> 0.011869431 | Q10: =IF(P10>0,1/P10^2,0) -> 7098.0689 | R10: 1 | S10: =IF(AND(R10=1,P10>0),1/(P10^2+$Y$13),0) -> 1650.1676 | T10: Unit assumed NO3 (= 2.107 mg/L N). Census-tract exposure
A11: Preterm <37wk | B11: Coffman | C11: 2022 | D11: In SR (Clemmensen 2023) | E11: Cohort | F11: Denmark | G11: 1009189 | H11: Per 10 mg/L NO3 (= 2.258 mg/L N) | I11: OR per 10 mg/L NO3 | J11: 1.02 | K11: 1 | L11: 1.03 | M11: perunit | N11: =EXP(LN(J11)*2.21405481999734) -> 1.0448195 | O11: =LN(J11)*2.21405481999734 -> 0.043844102 | P11: =((LN(L11)-LN(K11))/(2*1.959964))*2.21405481999734 -> 0.016695411 | Q11: =IF(P11>0,1/P11^2,0) -> 3587.6146 | R11: 1 | S11: =IF(AND(R11=1,P11>0),1/(P11^2+$Y$13),0) -> 1344.3527 | T11: Moderate preterm, continuous model
A12: Preterm <37wk | B12: Sherris-cont | C12: 2021 | D12: In SR (Clemmensen 2023) | E12: Cohort, within-mother | F12: USA (California) | G12: 1443318 | H12: Per 1 mg/L N (32-36wk) | I12: OR per 1 mg/L N | J12: 1.003 | K12: 1.001 | L12: 1.006 | M12: perunit | N12: =EXP(LN(J12)*5) -> 1.0150903 | O12: =LN(J12)*5 -> 0.014977545 | P12: =((LN(L12)-LN(K12))/(2*1.959964))*5 -> 0.0063554373 | Q12: =IF(P12>0,1/P12^2,0) -> 24757.633 | R12: 0 | S12: =IF(AND(R12=1,P12>0),1/(P12^2+$Y$13),0) -> 0 | T12: Continuous version of the same study - do not pool with its categorical estimate
B13: POOLED (all eligible) | J13: =IF(U13>0,EXP(AA13),"") -> 1.0684387 | K13: =IF(U13>0,EXP(AA13-1.959964*AB13),"") -> 1.0377173 | L13: =IF(U13>0,EXP(AA13+1.959964*AB13),"") -> 1.1000696 | M13: pooled | N13: =IF(U13>0,EXP(AA13),"") -> 1.0684387 | U13: =SUM($R$3:$R$12) -> 5 | V13: =IF(U13>0,SUMPRODUCT($R$3:$R$12,$Q$3:$Q$12,$O$3:$O$12)/SUMPRODUCT($R$3:$R$12,$Q$3:$Q$12),0) -> 0.055338537 | W13: =IF(U13>1,SUMPRODUCT($R$3:$R$12,$Q$3:$Q$12,($O$3:$O$12-V13)^2),0) -> 7.5597746 | X13: =IF(U13>1,SUMPRODUCT($R$3:$R$12,$Q$3:$Q$12)-SUMPRODUCT($R$3:$R$12,$Q$3:$Q$12,$Q$3:$Q$12)/SUMPRODUCT($R$3:$R$12,$Q$3:$Q$12),0) -> 7653.5255 | Y13: =IF(X13>0,MAX(0,(W13-(U13-1))/X13),0) -> 0.00046511566 | Z13: =IF(AND(U13>1,W13>0),MAX(0,(W13-(U13-1))/W13),0) -> 0.47088369 | AA13: =IF(SUM($S$3:$S$12)>0,SUMPRODUCT($S$3:$S$12,$O$3:$O$12)/SUM($S$3:$S$12),0) -> 0.066198434 | AB13: =IF(SUM($S$3:$S$12)>0,SQRT(1/SUM($S$3:$S$12)),0) -> 0.01488548
A15: Very preterm <32wk
A16: Very preterm <32wk | B16: Semprini | C16: 2026 | D16: Primary study | E16: Cohort (LPM, county FE) | F16: USA (Iowa) | G16: 113328 | H16: >=5 vs <=0.1 mg/L N | I16: RR from +0.526pp / 1.14% base | J16: 1.4614 | K16: 1.0693 | L16: 1.8535 | M16: cat5 | N16: =EXP(LN(J16)*1) -> 1.4614 | O16: =LN(J16)*1 -> 0.37939488 | P16: =((LN(L16)-LN(K16))/(2*1.959964))*1 -> 0.14032694 | Q16: =IF(P16>0,1/P16^2,0) -> 50.782943 | R16: 1 | S16: =IF(AND(R16=1,P16>0),1/(P16^2+$Y$24),0) -> 50.782943 | T16: Table 2
A17: Very preterm <32wk | B17: Semprini | C17: 2026 | D17: Primary study | E17: Cohort (LPM, county FE) | F17: USA (Iowa) | G17: 113328 | H17: >0.1 to <5 vs <=0.1 mg/L N | I17: RR from +0.170pp / 1.14% base | J17: 1.1491 | K17: 0.8237 | L17: 1.4746 | M17: sub5 | R17: 0 | S17: =IF(AND(R17=1,P17>0),1/(P17^2+$Y$24),0) -> 0 | T17: Intermediate category - null
A18: Very preterm <32wk | B18: Sherris | C18: 2021 | D18: Primary study + in SR | E18: Cohort, within-mother | F18: USA (California) | G18: 1443318 | H18: 5 to <10 vs <5 mg/L N (20-31wk) | I18: OR | J18: 1.47 | K18: 1.29 | L18: 1.67 | M18: cat5 | N18: =EXP(LN(J18)*1) -> 1.47 | O18: =LN(J18)*1 -> 0.3852624 | P18: =((LN(L18)-LN(K18))/(2*1.959964))*1 -> 0.065863814 | Q18: =IF(P18>0,1/P18^2,0) -> 230.51875 | R18: 1 | S18: =IF(AND(R18=1,P18>0),1/(P18^2+$Y$24),0) -> 230.51875 | T18: 20-31wk spontaneous PTB
A19: Very preterm <32wk | B19: Sherris | C19: 2021 | D19: Primary study + in SR | E19: Cohort, within-mother | F19: USA (California) | G19: 1443318 | H19: >=10 vs <5 mg/L N (20-31wk) | I19: OR | J19: 2.52 | K19: 1.49 | L19: 4.26 | M19: high | R19: 0 | S19: =IF(AND(R19=1,P19>0),1/(P19^2+$Y$24),0) -> 0 | T19: Above the MCL
A20: Very preterm <32wk | B20: Sherris | C20: 2021 | D20: Primary study + in SR | E20: Cohort, within-mother (no move) | F20: USA (California) | G20: 1443318 | H20: 5 to <10 vs <5 mg/L N (20-31wk) | I20: OR | J20: 1.64 | K20: 1.37 | L20: 1.97 | M20: alt | R20: 0 | S20: =IF(AND(R20=1,P20>0),1/(P20^2+$Y$24),0) -> 0 | T20: Siblings without maternal movement
A21: Very preterm <32wk | B21: Sherris | C21: 2021 | D21: Primary study + in SR | E21: Cohort, individual-level | F21: USA (California) | G21: 3832090 | H21: 5 to <10 vs <5 mg/L N (20-31wk) | I21: OR | J21: 1.49 | K21: 1.42 | L21: 1.56 | M21: alt | R21: 0 | S21: =IF(AND(R21=1,P21>0),1/(P21^2+$Y$24),0) -> 0 | T21: Individual-level design
A22: Very preterm <32wk | B22: Stayner | C22: 2017 | D22: In SR (Clemmensen 2023) | E22: Ecologic | F22: USA (OH/IN/IA/MO) | G22: 134258 | H22: Per 1 mg/L N | I22: RR per 1 mg/L N | J22: 1.08 | K22: 1.02 | L22: 1.15 | M22: perunit | N22: =EXP(LN(J22)*5) -> 1.4693281 | O22: =LN(J22)*5 -> 0.38480521 | P22: =((LN(L22)-LN(K22))/(2*1.959964))*5 -> 0.15301214 | Q22: =IF(P22>0,1/P22^2,0) -> 42.711834 | R22: 1 | S22: =IF(AND(R22=1,P22>0),1/(P22^2+$Y$24),0) -> 42.711834 | T22: Ecologic design. Counties with <20% private well users
A23: Very preterm <32wk | B23: Sherris-cont | C23: 2021 | D23: In SR (Clemmensen 2023) | E23: Cohort, within-mother | F23: USA (California) | G23: 1443318 | H23: Per 1 mg/L N (20-31wk) | I23: OR per 1 mg/L N | J23: 1.015 | K23: 1.008 | L23: 1.021 | M23: perunit | N23: =EXP(LN(J23)*5) -> 1.077284 | O23: =LN(J23)*5 -> 0.074443062 | P23: =((LN(L23)-LN(K23))/(2*1.959964))*5 -> 0.016345159 | Q23: =IF(P23>0,1/P23^2,0) -> 3743.016 | R23: 0 | S23: =IF(AND(R23=1,P23>0),1/(P23^2+$Y$24),0) -> 0 | T23: Continuous version of the same study
B24: POOLED (all eligible) | J24: =IF(U24>0,EXP(AA24),"") -> 1.4685603 | K24: =IF(U24>0,EXP(AA24-1.959964*AB24),"") -> 1.3170546 | L24: =IF(U24>0,EXP(AA24+1.959964*AB24),"") -> 1.6374942 | M24: pooled | N24: =IF(U24>0,EXP(AA24),"") -> 1.4685603 | U24: =SUM($R$16:$R$23) -> 3 | V24: =IF(U24>0,SUMPRODUCT($R$16:$R$23,$Q$16:$Q$23,$O$16:$O$23)/SUMPRODUCT($R$16:$R$23,$Q$16:$Q$23),0) -> 0.38428251 | W24: =IF(U24>1,SUMPRODUCT($R$16:$R$23,$Q$16:$Q$23,($O$16:$O$23-V24)^2),0) -> 0.00144616 | X24: =IF(U24>1,SUMPRODUCT($R$16:$R$23,$Q$16:$Q$23)-SUMPRODUCT($R$16:$R$23,$Q$16:$Q$23,$Q$16:$Q$23)/SUMPRODUCT($R$16:$R$23,$Q$16:$Q$23),0) -> 146.42186 | Y24: =IF(X24>0,MAX(0,(W24-(U24-1))/X24),0) -> 0 | Z24: =IF(AND(U24>1,W24>0),MAX(0,(W24-(U24-1))/W24),0) -> 0 | AA24: =IF(SUM($S$16:$S$23)>0,SUMPRODUCT($S$16:$S$23,$O$16:$O$23)/SUM($S$16:$S$23),0) -> 0.38428251 | AB24: =IF(SUM($S$16:$S$23)>0,SQRT(1/SUM($S$16:$S$23)),0) -> 0.055554396
A26: Low birthweight <2500g
A27: Low birthweight <2500g | B27: Semprini | C27: 2026 | D27: Primary study | E27: Cohort (LPM, county FE) | F27: USA (Iowa) | G27: 113328 | H27: >=5 vs <=0.1 mg/L N | I27: RR from -0.254pp / 4.30% base | J27: 0.9409 | K27: 0.8193 | L27: 1.0623 | M27: cat5 | N27: =EXP(LN(J27)*1) -> 0.9409 | O27: =LN(J27)*1 -> -0.060918415 | P27: =((LN(L27)-LN(K27))/(2*1.959964))*1 -> 0.066261761 | Q27: =IF(P27>0,1/P27^2,0) -> 227.75822 | R27: 1 | S27: =IF(AND(R27=1,P27>0),1/(P27^2+$Y$30),0) -> 40.973327 | T27: Table 2 - null, point estimate below 1
A28: Low birthweight <2500g | B28: Montoya | C28: 2025 | D28: Primary study | E28: Cohort (IV, water-system FE) | F28: USA (California) | G28: 338962 | H28: Any month 5-10 vs <5 mg/L N, trimester 2 | I28: RR from +0.010 / 0.06 mean | J28: 1.1667 | K28: 1.0687 | L28: 1.2647 | M28: cat5 | N28: =EXP(LN(J28)*1) -> 1.1667 | O28: =LN(J28)*1 -> 0.15417925 | P28: =((LN(L28)-LN(K28))/(2*1.959964))*1 -> 0.042957928 | Q28: =IF(P28>0,1/P28^2,0) -> 541.89277 | R28: 1 | S28: =IF(AND(R28=1,P28>0),1/(P28^2+$Y$30),0) -> 45.743804 | T28: Table 2 Panel B, full-gestation IV (preferred)
A29: Low birthweight <2500g | B29: Montoya | C29: 2025 | D29: Primary study | E29: Cohort (no IV) | F29: USA (California) | G29: 338962 | H29: Any month 5-10 vs <5 mg/L N, trimester 2 | I29: RR from +0.017 / 0.06 mean | J29: 1.2833 | K29: 1.1853 | L29: 1.3813 | M29: alt | R29: 0 | S29: =IF(AND(R29=1,P29>0),1/(P29^2+$Y$30),0) -> 0 | T29: Non-instrumented specification
B30: POOLED (all eligible) | J30: =IF(U30>0,EXP(AA30),"") -> 1.053952 | K30: =IF(U30>0,EXP(AA30-1.959964*AB30),"") -> 0.85391318 | L30: =IF(U30>0,EXP(AA30+1.959964*AB30),"") -> 1.3008521 | M30: pooled | N30: =IF(U30>0,EXP(AA30),"") -> 1.053952 | U30: =SUM($R$27:$R$29) -> 2 | V30: =IF(U30>0,SUMPRODUCT($R$27:$R$29,$Q$27:$Q$29,$O$27:$O$29)/SUMPRODUCT($R$27:$R$29,$Q$27:$Q$29),0) -> 0.090526684 | W30: =IF(U30>1,SUMPRODUCT($R$27:$R$29,$Q$27:$Q$29,($O$27:$O$29-V30)^2),0) -> 7.4193349 | X30: =IF(U30>1,SUMPRODUCT($R$27:$R$29,$Q$27:$Q$29)-SUMPRODUCT($R$27:$R$29,$Q$27:$Q$29,$Q$27:$Q$29)/SUMPRODUCT($R$27:$R$29,$Q$27:$Q$29),0) -> 320.71818 | Y30: =IF(X30>0,MAX(0,(W30-(U30-1))/X30),0) -> 0.020015501 | Z30: =IF(AND(U30>1,W30>0),MAX(0,(W30-(U30-1))/W30),0) -> 0.86521703 | AA30: =IF(SUM($S$27:$S$29)>0,SUMPRODUCT($S$27:$S$29,$O$27:$O$29)/SUM($S$27:$S$29),0) -> 0.052546887 | AB30: =IF(SUM($S$27:$S$29)>0,SQRT(1/SUM($S$27:$S$29)),0) -> 0.10738597
A32: Very low birthweight <1500g
A33: Very low birthweight <1500g | B33: Semprini | C33: 2026 | D33: Primary study | E33: Cohort (LPM, county FE) | F33: USA (Iowa) | G33: 113328 | H33: >=5 vs <=0.1 mg/L N | I33: RR from +0.245pp / 0.64% base | J33: 1.3828 | K33: 0.9969 | L33: 1.7688 | M33: cat5 | N33: =EXP(LN(J33)*1) -> 1.3828 | O33: =LN(J33)*1 -> 0.32411043 | P33: =((LN(L33)-LN(K33))/(2*1.959964))*1 -> 0.14627977 | Q33: =IF(P33>0,1/P33^2,0) -> 46.73384 | R33: 1 | S33: =IF(AND(R33=1,P33>0),1/(P33^2+$Y$35),0) -> 10.046886 | T33: Table 2; p=0.052. Significant in Table 4 binary spec
A34: Very low birthweight <1500g | B34: Stayner | C34: 2017 | D34: In SR (Clemmensen 2023) | E34: Ecologic | F34: USA (OH/IN/IA/MO) | G34: 134258 | H34: Per 1 mg/L N | I34: RR per 1 mg/L N | J34: 1.17 | K34: 1.08 | L34: 1.25 | M34: perunit | N34: =EXP(LN(J34)*5) -> 2.192448 | O34: =LN(J34)*5 -> 0.78501874 | P34: =((LN(L34)-LN(K34))/(2*1.959964))*5 -> 0.18646071 | Q34: =IF(P34>0,1/P34^2,0) -> 28.762415 | R34: 1 | S34: =IF(AND(R34=1,P34>0),1/(P34^2+$Y$35),0) -> 8.8571488 | T34: Ecologic design
B35: POOLED (all eligible) | J35: =IF(U35>0,EXP(AA35),"") -> 1.7161112 | K35: =IF(U35>0,EXP(AA35-1.959964*AB35),"") -> 1.0933806 | L35: =IF(U35>0,EXP(AA35+1.959964*AB35),"") -> 2.6935156 | M35: pooled | N35: =IF(U35>0,EXP(AA35),"") -> 1.7161112 | U35: =SUM($R$33:$R$34) -> 2 | V35: =IF(U35>0,SUMPRODUCT($R$33:$R$34,$Q$33:$Q$34,$O$33:$O$34)/SUMPRODUCT($R$33:$R$34,$Q$33:$Q$34),0) -> 0.49970637 | W35: =IF(U35>1,SUMPRODUCT($R$33:$R$34,$Q$33:$Q$34,($O$33:$O$34-V35)^2),0) -> 3.7823393 | X35: =IF(U35>1,SUMPRODUCT($R$33:$R$34,$Q$33:$Q$34)-SUMPRODUCT($R$33:$R$34,$Q$33:$Q$34,$Q$33:$Q$34)/SUMPRODUCT($R$33:$R$34,$Q$33:$Q$34),0) -> 35.609133 | Y35: =IF(X35>0,MAX(0,(W35-(U35-1))/X35),0) -> 0.078135554 | Z35: =IF(AND(U35>1,W35>0),MAX(0,(W35-(U35-1))/W35),0) -> 0.73561336 | AA35: =IF(SUM($S$33:$S$34)>0,SUMPRODUCT($S$33:$S$34,$O$33:$O$34)/SUM($S$33:$S$34),0) -> 0.54006081 | AB35: =IF(SUM($S$33:$S$34)>0,SQRT(1/SUM($S$33:$S$34)),0) -> 0.2299973
A37: Stillbirth
A38: Stillbirth | B38: Thomsen | C38: 2021 | D38: In SR (Clemmensen 2023) | E38: Cohort | F38: Denmark | G38: 652810 | H38: >25 mg/L NO3, nitratable-drug subgroup | I38: HR | J38: 3.11 | K38: 1.08 | L38: 8.94 | M38: other | R38: 0 | S38: =IF(AND(R38=1,P38>0),1/(P38^2+$Y$39),0) -> 0 | T38: Subgroup only; no overall association
B39: POOLED (all eligible) | J39: =IF(U39>0,EXP(AA39),"") | K39: =IF(U39>0,EXP(AA39-1.959964*AB39),"") | L39: =IF(U39>0,EXP(AA39+1.959964*AB39),"") | M39: pooled | N39: =IF(U39>0,EXP(AA39),"") | U39: =SUM($R$38:$R$38) -> 0 | V39: =IF(U39>0,SUMPRODUCT($R$38:$R$38,$Q$38:$Q$38,$O$38:$O$38)/SUMPRODUCT($R$38:$R$38,$Q$38:$Q$38),0) -> 0 | W39: =IF(U39>1,SUMPRODUCT($R$38:$R$38,$Q$38:$Q$38,($O$38:$O$38-V39)^2),0) -> 0 | X39: =IF(U39>1,SUMPRODUCT($R$38:$R$38,$Q$38:$Q$38)-SUMPRODUCT($R$38:$R$38,$Q$38:$Q$38,$Q$38:$Q$38)/SUMPRODUCT($R$38:$R$38,$Q$38:$Q$38),0) -> 0 | Y39: =IF(X39>0,MAX(0,(W39-(U39-1))/X39),0) -> 0 | Z39: =IF(AND(U39>1,W39>0),MAX(0,(W39-(U39-1))/W39),0) -> 0 | AA39: =IF(SUM($S$38:$S$38)>0,SUMPRODUCT($S$38:$S$38,$O$38:$O$38)/SUM($S$38:$S$38),0) -> 0 | AB39: =IF(SUM($S$38:$S$38)>0,SQRT(1/SUM($S$38:$S$38)),0) -> 0
A41: Birth defects - eye
A42: Birth defects - eye | B42: Stayner | C42: 2022 | D42: In SR (Clemmensen 2023) | E42: Cohort | F42: Denmark | G42: 1018914 | H42: >=25 mg/L NO3 | I42: OR | J42: 1.29 | K42: 1 | L42: 1.66 | M42: other | R42: 0 | S42: =IF(AND(R42=1,P42>0),1/(P42^2+$Y$43),0) -> 0 | T42: Eye defects; other defect groups null overall
B43: POOLED (all eligible) | J43: =IF(U43>0,EXP(AA43),"") | K43: =IF(U43>0,EXP(AA43-1.959964*AB43),"") | L43: =IF(U43>0,EXP(AA43+1.959964*AB43),"") | M43: pooled | N43: =IF(U43>0,EXP(AA43),"") | U43: =SUM($R$42:$R$42) -> 0 | V43: =IF(U43>0,SUMPRODUCT($R$42:$R$42,$Q$42:$Q$42,$O$42:$O$42)/SUMPRODUCT($R$42:$R$42,$Q$42:$Q$42),0) -> 0 | W43: =IF(U43>1,SUMPRODUCT($R$42:$R$42,$Q$42:$Q$42,($O$42:$O$42-V43)^2),0) -> 0 | X43: =IF(U43>1,SUMPRODUCT($R$42:$R$42,$Q$42:$Q$42)-SUMPRODUCT($R$42:$R$42,$Q$42:$Q$42,$Q$42:$Q$42)/SUMPRODUCT($R$42:$R$42,$Q$42:$Q$42),0) -> 0 | Y43: =IF(X43>0,MAX(0,(W43-(U43-1))/X43),0) -> 0 | Z43: =IF(AND(U43>1,W43>0),MAX(0,(W43-(U43-1))/W43),0) -> 0 | AA43: =IF(SUM($S$42:$S$42)>0,SUMPRODUCT($S$42:$S$42,$O$42:$O$42)/SUM($S$42:$S$42),0) -> 0 | AB43: =IF(SUM($S$42:$S$42)>0,SQRT(1/SUM($S$42:$S$42)),0) -> 0
A45: Birth defects - limb
A46: Birth defects - limb | B46: Blaisdell | C46: 2019 | D46: In SR (Clemmensen 2023) | E46: Cohort | F46: USA (Missouri) | G46: 348250 | H46: Per 1 mg/L N | I46: RR per 1 mg/L N | J46: 1.26 | K46: 1.05 | L46: 1.51 | M46: other | R46: 0 | S46: =IF(AND(R46=1,P46>0),1/(P46^2+$Y$47),0) -> 0 | T46: Limb deficiency. County-level exposure
...

Sheet Pooled comparisons
A1: Pooled multipliers by outcome and by study set
A2: All estimates on a common contrast: roughly 5 to 10 mg/L nitrate-N versus below 5 (or near zero). Studies reporting per-unit estimates are rescaled to a 5 mg/L-N increment by log-linear extrapolation - see the 'Scale and overlap' sheet for what that assumption costs. DerSimonian-Laird random effects.
A4: Outcome | B4: Study set | C4: Studies included | D4: k | E4: Pooled multiplier | F4: 95% LCL | G4: 95% UCL | H4: I^2 | I4: Flag | J4: k | K4: FE | L4: Q | M4: C | N4: tau^2 | O4: I^2 | P4: mu | Q4: SE(mu)
A5: Preterm <37wk | B5: 1. Semprini + Montoya + Sherris | C5: Semprini 2026, Montoya 2025, Sherris 2021 | D5: =J5 -> 3 | E5: =EXP(P5) -> 1.1097683 | F5: =EXP(P5-1.959964*Q5) -> 1.0628549 | G5: =EXP(P5+1.959964*Q5) -> 1.1587523 | H5: =IF(J5>1,O5,"") -> 0 | J5: 3 | K5: =SUMPRODUCT(1/$B$120:$B$122^2,$A$120:$A$122)/SUMPRODUCT(1/$B$120:$B$122^2) -> 0.10415122 | L5: =IF(J5>1,SUMPRODUCT(1/$B$120:$B$122^2,($A$120:$A$122-K5)^2),0) -> 1.6846408 | M5: =IF(J5>1,SUMPRODUCT(1/$B$120:$B$122^2)-SUMPRODUCT(1/$B$120:$B$122^2,1/$B$120:$B$122^2)/SUMPRODUCT(1/$B$120:$B$122^2),0) -> 1265.8298 | N5: =IF(M5>0,MAX(0,(L5-(J5-1))/M5),0) -> 0 | O5: =IF(AND(J5>1,L5>0),MAX(0,(L5-(J5-1))/L5),0) -> 0 | P5: =SUMPRODUCT(1/($B$120:$B$122^2+N5),$A$120:$A$122)/SUMPRODUCT(1/($B$120:$B$122^2+N5)) -> 0.10415122 | Q5: =SQRT(1/SUMPRODUCT(1/($B$120:$B$122^2+N5))) -> 0.022037446
A6: Preterm <37wk | B6: 2. SR evidence base (Clemmensen) | C6: Huang 2018, Coffman 2022 | D6: =J6 -> 2 | E6: =EXP(P6) -> 1.0470037 | F6: =EXP(P6-1.959964*Q6) -> 1.0273391 | G6: =EXP(P6+1.959964*Q6) -> 1.0670447 | H6: =IF(J6>1,O6,"") -> 0 | J6: 2 | K6: =SUMPRODUCT(1/$B$124:$B$125^2,$A$124:$A$125)/SUMPRODUCT(1/$B$124:$B$125^2) -> 0.045932474 | L6: =IF(J6>1,SUMPRODUCT(1/$B$124:$B$125^2,($A$124:$A$125-K6)^2),0) -> 0.023555019 | M6: =IF(J6>1,SUMPRODUCT(1/$B$124:$B$125^2)-SUMPRODUCT(1/$B$124:$B$125^2,1/$B$124:$B$125^2)/SUMPRODUCT(1/$B$124:$B$125^2),0) -> 4766.2155 | N6: =IF(M6>0,MAX(0,(L6-(J6-1))/M6),0) -> 0 | O6: =IF(AND(J6>1,L6>0),MAX(0,(L6-(J6-1))/L6),0) -> 0 | P6: =SUMPRODUCT(1/($B$124:$B$125^2+N6),$A$124:$A$125)/SUMPRODUCT(1/($B$124:$B$125^2+N6)) -> 0.045932474 | Q6: =SQRT(1/SUMPRODUCT(1/($B$124:$B$125^2+N6))) -> 0.0096738388
A7: Preterm <37wk | B7: 3. Semprini + SR | C7: Semprini 2026, Huang 2018, Coffman 2022 | D7: =J7 -> 3 | E7: =EXP(P7) -> 1.0528969 | F7: =EXP(P7-1.959964*Q7) -> 1.0264974 | G7: =EXP(P7+1.959964*Q7) -> 1.0799754 | H7: =IF(J7>1,O7,"") -> 0.31025505 | J7: 3 | K7: =SUMPRODUCT(1/$B$127:$B$129^2,$A$127:$A$129)/SUMPRODUCT(1/$B$127:$B$129^2) -> 0.049282309 | L7: =IF(J7>1,SUMPRODUCT(1/$B$127:$B$129^2,($A$127:$A$129-K7)^2),0) -> 2.8996225 | M7: =IF(J7>1,SUMPRODUCT(1/$B$127:$B$129^2)-SUMPRODUCT(1/$B$127:$B$129^2,1/$B$127:$B$129^2)/SUMPRODUCT(1/$B$127:$B$129^2),0) -> 5458.5131 | N7: =IF(M7>0,MAX(0,(L7-(J7-1))/M7),0) -> 0.00016481091 | O7: =IF(AND(J7>1,L7>0),MAX(0,(L7-(J7-1))/L7),0) -> 0.31025505 | P7: =SUMPRODUCT(1/($B$127:$B$129^2+N7),$A$127:$A$129)/SUMPRODUCT(1/($B$127:$B$129^2+N7)) -> 0.051545297 | Q7: =SQRT(1/SUMPRODUCT(1/($B$127:$B$129^2+N7))) -> 0.01295581
A8: Preterm <37wk | B8: 4. Montoya + SR | C8: Montoya 2025, Huang 2018, Coffman 2022 | D8: =J8 -> 3 | E8: =EXP(P8) -> 1.0586069 | F8: =EXP(P8-1.959964*Q8) -> 1.0243024 | G8: =EXP(P8+1.959964*Q8) -> 1.0940603 | H8: =IF(J8>1,O8,"") -> 0.54960267 | J8: 3 | K8: =SUMPRODUCT(1/$B$131:$B$133^2,$A$131:$A$133)/SUMPRODUCT(1/$B$131:$B$133^2) -> 0.050337848 | L8: =IF(J8>1,SUMPRODUCT(1/$B$131:$B$133^2,($A$131:$A$133-K8)^2),0) -> 4.4405236 | M8: =IF(J8>1,SUMPRODUCT(1/$B$131:$B$133^2)-SUMPRODUCT(1/$B$131:$B$133^2,1/$B$131:$B$133^2)/SUMPRODUCT(1/$B$131:$B$133^2),0) -> 5545.8416 | N8: =IF(M8>0,MAX(0,(L8-(J8-1))/M8),0) -> 0.00044006371 | O8: =IF(AND(J8>1,L8>0),MAX(0,(L8-(J8-1))/L8),0) -> 0.54960267 | P8: =SUMPRODUCT(1/($B$131:$B$133^2+N8),$A$131:$A$133)/SUMPRODUCT(1/($B$131:$B$133^2+N8)) -> 0.056953804 | Q8: =SQRT(1/SUMPRODUCT(1/($B$131:$B$133^2+N8))) -> 0.016807459
A9: Preterm <37wk | B9: 5. Sherris + SR | C9: Sherris 2021, Huang 2018, Coffman 2022 | D9: =J9 -> 3 | E9: =EXP(P9) -> 1.0499593 | F9: =EXP(P9-1.959964*Q9) -> 1.0311481 | G9: =EXP(P9+1.959964*Q9) -> 1.0691137 | H9: =IF(J9>1,O9,"") -> 0 | I9: Sherris is INSIDE the SR. SR set shown here excludes it to avoid double counting. | J9: 3 | K9: =SUMPRODUCT(1/$B$135:$B$137^2,$A$135:$A$137)/SUMPRODUCT(1/$B$135:$B$137^2) -> 0.048751399 | L9: =IF(J9>1,SUMPRODUCT(1/$B$135:$B$137^2,($A$135:$A$137-K9)^2),0) -> 0.95820182 | M9: =IF(J9>1,SUMPRODUCT(1/$B$135:$B$137^2)-SUMPRODUCT(1/$B$135:$B$137^2,1/$B$135:$B$137^2)/SUMPRODUCT(1/$B$135:$B$137^2),0) -> 6274.7826 | N9: =IF(M9>0,MAX(0,(L9-(J9-1))/M9),0) -> 0 | O9: =IF(AND(J9>1,L9>0),MAX(0,(L9-(J9-1))/L9),0) -> 0 | P9: =SUMPRODUCT(1/($B$135:$B$137^2+N9),$A$135:$A$137)/SUMPRODUCT(1/($B$135:$B$137^2+N9)) -> 0.048751399 | Q9: =SQRT(1/SUMPRODUCT(1/($B$135:$B$137^2+N9))) -> 0.0092239465
A10: Preterm <37wk | B10: 6. All studies combined | C10: Semprini 2026, Montoya 2025, Sherris 2021, Huang 2018, Coffman 2022 | D10: =J10 -> 5 | E10: =EXP(P10) -> 1.0684387 | F10: =EXP(P10-1.959964*Q10) -> 1.0377173 | G10: =EXP(P10+1.959964*Q10) -> 1.1000696 | H10: =IF(J10>1,O10,"") -> 0.47088369 | J10: 5 | K10: =SUMPRODUCT(1/$B$139:$B$143^2,$A$139:$A$143)/SUMPRODUCT(1/$B$139:$B$143^2) -> 0.055338537 | L10: =IF(J10>1,SUMPRODUCT(1/$B$139:$B$143^2,($A$139:$A$143-K10)^2),0) -> 7.5597746 | M10: =IF(J10>1,SUMPRODUCT(1/$B$139:$B$143^2)-SUMPRODUCT(1/$B$139:$B$143^2,1/$B$139:$B$143^2)/SUMPRODUCT(1/$B$139:$B$143^2),0) -> 7653.5255 | N10: =IF(M10>0,MAX(0,(L10-(J10-1))/M10),0) -> 0.00046511566 | O10: =IF(AND(J10>1,L10>0),MAX(0,(L10-(J10-1))/L10),0) -> 0.47088369 | P10: =SUMPRODUCT(1/($B$139:$B$143^2+N10),$A$139:$A$143)/SUMPRODUCT(1/($B$139:$B$143^2+N10)) -> 0.066198434 | Q10: =SQRT(1/SUMPRODUCT(1/($B$139:$B$143^2+N10))) -> 0.01488548
A12: Very preterm <32wk | B12: 1. Semprini + Montoya + Sherris | C12: Semprini 2026, Sherris 2021 | D12: =J12 -> 2 | E12: =EXP(P12) -> 1.4684437 | F12: =EXP(P12-1.959964*Q12) -> 1.3064901 | G12: =EXP(P12+1.959964*Q12) -> 1.6504733 | H12: =IF(J12>1,O12,"") -> 0 | J12: 2 | K12: =SUMPRODUCT(1/$B$145:$B$146^2,$A$145:$A$146)/SUMPRODUCT(1/$B$145:$B$146^2) -> 0.38420315 | L12: =IF(J12>1,SUMPRODUCT(1/$B$145:$B$146^2,($A$145:$A$146-K12)^2),0) -> 0.0014327189 | M12: =IF(J12>1,SUMPRODUCT(1/$B$145:$B$146^2)-SUMPRODUCT(1/$B$145:$B$146^2,1/$B$145:$B$146^2)/SUMPRODUCT(1/$B$145:$B$146^2),0) -> 83.23036 | N12: =IF(M12>0,MAX(0,(L12-(J12-1))/M12),0) -> 0 | O12: =IF(AND(J12>1,L12>0),MAX(0,(L12-(J12-1))/L12),0) -> 0 | P12: =SUMPRODUCT(1/($B$145:$B$146^2+N12),$A$145:$A$146)/SUMPRODUCT(1/($B$145:$B$146^2+N12)) -> 0.38420315 | Q12: =SQRT(1/SUMPRODUCT(1/($B$145:$B$146^2+N12))) -> 0.059623001
A13: Very preterm <32wk | B13: 2. SR evidence base (Clemmensen) | C13: Stayner 2017 | D13: =J13 -> 1 | E13: =EXP(P13) -> 1.4693281 | F13: =EXP(P13-1.959964*Q13) -> 1.0886157 | G13: =EXP(P13+1.959964*Q13) -> 1.9831837 | H13: =IF(J13>1,O13,"") | J13: 1 | K13: =SUMPRODUCT(1/$B$148:$B$148^2,$A$148:$A$148)/SUMPRODUCT(1/$B$148:$B$148^2) -> 0.38480521 | L13: =IF(J13>1,SUMPRODUCT(1/$B$148:$B$148^2,($A$148:$A$148-K13)^2),0) -> 0 | M13: =IF(J13>1,SUMPRODUCT(1/$B$148:$B$148^2)-SUMPRODUCT(1/$B$148:$B$148^2,1/$B$148:$B$148^2)/SUMPRODUCT(1/$B$148:$B$148^2),0) -> 0 | N13: =IF(M13>0,MAX(0,(L13-(J13-1))/M13),0) -> 0 | O13: =IF(AND(J13>1,L13>0),MAX(0,(L13-(J13-1))/L13),0) -> 0 | P13: =SUMPRODUCT(1/($B$148:$B$148^2+N13),$A$148:$A$148)/SUMPRODUCT(1/($B$148:$B$148^2+N13)) -> 0.38480521 | Q13: =SQRT(1/SUMPRODUCT(1/($B$148:$B$148^2+N13))) -> 0.15301214
A14: Very preterm <32wk | B14: 3. Semprini + SR | C14: Semprini 2026, Stayner 2017 | D14: =J14 -> 2 | E14: =EXP(P14) -> 1.4650165 | F14: =EXP(P14-1.959964*Q14) -> 1.1962195 | G14: =EXP(P14+1.959964*Q14) -> 1.7942136 | H14: =IF(J14>1,O14,"") -> 0 | J14: 2 | K14: =SUMPRODUCT(1/$B$150:$B$151^2,$A$150:$A$151)/SUMPRODUCT(1/$B$150:$B$151^2) -> 0.38186651 | L14: =IF(J14>1,SUMPRODUCT(1/$B$150:$B$151^2,($A$150:$A$151-K14)^2),0) -> 0.00067908712 | M14: =IF(J14>1,SUMPRODUCT(1/$B$150:$B$151^2)-SUMPRODUCT(1/$B$150:$B$151^2,1/$B$150:$B$151^2)/SUMPRODUCT(1/$B$150:$B$151^2),0) -> 46.399012 | N14: =IF(M14>0,MAX(0,(L14-(J14-1))/M14),0) -> 0 | O14: =IF(AND(J14>1,L14>0),MAX(0,(L14-(J14-1))/L14),0) -> 0 | P14: =SUMPRODUCT(1/($B$150:$B$151^2+N14),$A$150:$A$151)/SUMPRODUCT(1/($B$150:$B$151^2+N14)) -> 0.38186651 | Q14: =SQRT(1/SUMPRODUCT(1/($B$150:$B$151^2+N14))) -> 0.10342043
A15: Very preterm <32wk | B15: 4. Montoya + SR | C15: Stayner 2017 | D15: =J15 -> 1 | E15: =EXP(P15) -> 1.4693281 | F15: =EXP(P15-1.959964*Q15) -> 1.0886157 | G15: =EXP(P15+1.959964*Q15) -> 1.9831837 | H15: =IF(J15>1,O15,"") | J15: 1 | K15: =SUMPRODUCT(1/$B$153:$B$153^2,$A$153:$A$153)/SUMPRODUCT(1/$B$153:$B$153^2) -> 0.38480521 | L15: =IF(J15>1,SUMPRODUCT(1/$B$153:$B$153^2,($A$153:$A$153-K15)^2),0) -> 0 | M15: =IF(J15>1,SUMPRODUCT(1/$B$153:$B$153^2)-SUMPRODUCT(1/$B$153:$B$153^2,1/$B$153:$B$153^2)/SUMPRODUCT(1/$B$153:$B$153^2),0) -> 0 | N15: =IF(M15>0,MAX(0,(L15-(J15-1))/M15),0) -> 0 | O15: =IF(AND(J15>1,L15>0),MAX(0,(L15-(J15-1))/L15),0) -> 0 | P15: =SUMPRODUCT(1/($B$153:$B$153^2+N15),$A$153:$A$153)/SUMPRODUCT(1/($B$153:$B$153^2+N15)) -> 0.38480521 | Q15: =SQRT(1/SUMPRODUCT(1/($B$153:$B$153^2+N15))) -> 0.15301214
A16: Very preterm <32wk | B16: 5. Sherris + SR | C16: Sherris 2021, Stayner 2017 | D16: =J16 -> 2 | E16: =EXP(P16) -> 1.4698949 | F16: =EXP(P16-1.959964*Q16) -> 1.3055424 | G16: =EXP(P16+1.959964*Q16) -> 1.6549376 | H16: =IF(J16>1,O16,"") -> 0 | I16: Sherris is INSIDE the SR. SR set shown here excludes it to avoid double counting. | J16: 2 | K16: =SUMPRODUCT(1/$B$155:$B$156^2,$A$155:$A$156)/SUMPRODUCT(1/$B$155:$B$156^2) -> 0.38519093 | L16: =IF(J16>1,SUMPRODUCT(1/$B$155:$B$156^2,($A$155:$A$156-K16)^2),0) -> 7.5323122e-06 | M16: =IF(J16>1,SUMPRODUCT(1/$B$155:$B$156^2)-SUMPRODUCT(1/$B$155:$B$156^2,1/$B$155:$B$156^2)/SUMPRODUCT(1/$B$155:$B$156^2),0) -> 72.070105 | N16: =IF(M16>0,MAX(0,(L16-(J16-1))/M16),0) -> 0 | O16: =IF(AND(J16>1,L16>0),MAX(0,(L16-(J16-1))/L16),0) -> 0 | P16: =SUMPRODUCT(1/($B$155:$B$156^2+N16),$A$155:$A$156)/SUMPRODUCT(1/($B$155:$B$156^2+N16)) -> 0.38519093 | Q16: =SQRT(1/SUMPRODUCT(1/($B$155:$B$156^2+N16))) -> 0.06049721
A17: Very preterm <32wk | B17: 6. All studies combined | C17: Semprini 2026, Sherris 2021, Stayner 2017 | D17: =J17 -> 3 | E17: =EXP(P17) -> 1.4685603 | F17: =EXP(P17-1.959964*Q17) -> 1.3170546 | G17: =EXP(P17+1.959964*Q17) -> 1.6374942 | H17: =IF(J17>1,O17,"") -> 0 | J17: 3 | K17: =SUMPRODUCT(1/$B$158:$B$160^2,$A$158:$A$160)/SUMPRODUCT(1/$B$158:$B$160^2) -> 0.38428251 | L17: =IF(J17>1,SUMPRODUCT(1/$B$158:$B$160^2,($A$158:$A$160-K17)^2),0) -> 0.00144616 | M17: =IF(J17>1,SUMPRODUCT(1/$B$158:$B$160^2)-SUMPRODUCT(1/$B$158:$B$160^2,1/$B$158:$B$160^2)/SUMPRODUCT(1/$B$158:$B$160^2),0) -> 146.42186 | N17: =IF(M17>0,MAX(0,(L17-(J17-1))/M17),0) -> 0 | O17: =IF(AND(J17>1,L17>0),MAX(0,(L17-(J17-1))/L17),0) -> 0 | P17: =SUMPRODUCT(1/($B$158:$B$160^2+N17),$A$158:$A$160)/SUMPRODUCT(1/($B$158:$B$160^2+N17)) -> 0.38428251 | Q17: =SQRT(1/SUMPRODUCT(1/($B$158:$B$160^2+N17))) -> 0.055554396
A19: Low birthweight <2500g | B19: 1. Semprini + Montoya + Sherris | C19: Semprini 2026, Montoya 2025 | D19: =J19 -> 2 | E19: =EXP(P19) -> 1.053952 | F19: =EXP(P19-1.959964*Q19) -> 0.85391318 | G19: =EXP(P19+1.959964*Q19) -> 1.3008521 | H19: =IF(J19>1,O19,"") -> 0.86521703 | J19: 2 | K19: =SUMPRODUCT(1/$B$162:$B$163^2,$A$162:$A$163)/SUMPRODUCT(1/$B$162:$B$163^2) -> 0.090526684 | L19: =IF(J19>1,SUMPRODUCT(1/$B$162:$B$163^2,($A$162:$A$163-K19)^2),0) -> 7.4193349 | M19: =IF(J19>1,SUMPRODUCT(1/$B$162:$B$163^2)-SUMPRODUCT(1/$B$162:$B$163^2,1/$B$162:$B$163^2)/SUMPRODUCT(1/$B$162:$B$163^2),0) -> 320.71818 | N19: =IF(M19>0,MAX(0,(L19-(J19-1))/M19),0) -> 0.020015501 | O19: =IF(AND(J19>1,L19>0),MAX(0,(L19-(J19-1))/L19),0) -> 0.86521703 | P19: =SUMPRODUCT(1/($B$162:$B$163^2+N19),$A$162:$A$163)/SUMPRODUCT(1/($B$162:$B$163^2+N19)) -> 0.052546887 | Q19: =SQRT(1/SUMPRODUCT(1/($B$162:$B$163^2+N19))) -> 0.10738597
A20: Low birthweight <2500g | B20: 2. SR evidence base (Clemmensen) | C20: none | D20: 0
A21: Low birthweight <2500g | B21: 3. Semprini + SR | C21: Semprini 2026 | D21: =J21 -> 1 | E21: =EXP(P21) -> 0.9409 | F21: =EXP(P21-1.959964*Q21) -> 0.82630685 | G21: =EXP(P21+1.959964*Q21) -> 1.071385 | H21: =IF(J21>1,O21,"") | J21: 1 | K21: =SUMPRODUCT(1/$B$165:$B$165^2,$A$165:$A$165)/SUMPRODUCT(1/$B$165:$B$165^2) -> -0.060918415 | L21: =IF(J21>1,SUMPRODUCT(1/$B$165:$B$165^2,($A$165:$A$165-K21)^2),0) -> 0 | M21: =IF(J21>1,SUMPRODUCT(1/$B$165:$B$165^2)-SUMPRODUCT(1/$B$165:$B$165^2,1/$B$165:$B$165^2)/SUMPRODUCT(1/$B$165:$B$165^2),0) -> 0 | N21: =IF(M21>0,MAX(0,(L21-(J21-1))/M21),0) -> 0 | O21: =IF(AND(J21>1,L21>0),MAX(0,(L21-(J21-1))/L21),0) -> 0 | P21: =SUMPRODUCT(1/($B$165:$B$165^2+N21),$A$165:$A$165)/SUMPRODUCT(1/($B$165:$B$165^2+N21)) -> -0.060918415 | Q21: =SQRT(1/SUMPRODUCT(1/($B$165:$B$165^2+N21))) -> 0.066261761
A22: Low birthweight <2500g | B22: 4. Montoya + SR | C22: Montoya 2025 | D22: =J22 -> 1 | E22: =EXP(P22) -> 1.1667 | F22: =EXP(P22-1.959964*Q22) -> 1.0724902 | G22: =EXP(P22+1.959964*Q22) -> 1.2691854 | H22: =IF(J22>1,O22,"") | J22: 1 | K22: =SUMPRODUCT(1/$B$167:$B$167^2,$A$167:$A$167)/SUMPRODUCT(1/$B$167:$B$167^2) -> 0.15417925 | L22: =IF(J22>1,SUMPRODUCT(1/$B$167:$B$167^2,($A$167:$A$167-K22)^2),0) -> 0 | M22: =IF(J22>1,SUMPRODUCT(1/$B$167:$B$167^2)-SUMPRODUCT(1/$B$167:$B$167^2,1/$B$167:$B$167^2)/SUMPRODUCT(1/$B$167:$B$167^2),0) -> 0 | N22: =IF(M22>0,MAX(0,(L22-(J22-1))/M22),0) -> 0 | O22: =IF(AND(J22>1,L22>0),MAX(0,(L22-(J22-1))/L22),0) -> 0 | P22: =SUMPRODUCT(1/($B$167:$B$167^2+N22),$A$167:$A$167)/SUMPRODUCT(1/($B$167:$B$167^2+N22)) -> 0.15417925 | Q22: =SQRT(1/SUMPRODUCT(1/($B$167:$B$167^2+N22))) -> 0.042957928
A23: Low birthweight <2500g | B23: 5. Sherris + SR | C23: none | D23: 0 | I23: Sherris is INSIDE the SR. SR set shown here excludes it to avoid double counting.
A24: Low birthweight <2500g | B24: 6. All studies combined | C24: Semprini 2026, Montoya 2025 | D24: =J24 -> 2 | E24: =EXP(P24) -> 1.053952 | F24: =EXP(P24-1.959964*Q24) -> 0.85391318 | G24: =EXP(P24+1.959964*Q24) -> 1.3008521 | H24: =IF(J24>1,O24,"") -> 0.86521703 | J24: 2 | K24: =SUMPRODUCT(1/$B$169:$B$170^2,$A$169:$A$170)/SUMPRODUCT(1/$B$169:$B$170^2) -> 0.090526684 | L24: =IF(J24>1,SUMPRODUCT(1/$B$169:$B$170^2,($A$169:$A$170-K24)^2),0) -> 7.4193349 | M24: =IF(J24>1,SUMPRODUCT(1/$B$169:$B$170^2)-SUMPRODUCT(1/$B$169:$B$170^2,1/$B$169:$B$170^2)/SUMPRODUCT(1/$B$169:$B$170^2),0) -> 320.71818 | N24: =IF(M24>0,MAX(0,(L24-(J24-1))/M24),0) -> 0.020015501 | O24: =IF(AND(J24>1,L24>0),MAX(0,(L24-(J24-1))/L24),0) -> 0.86521703 | P24: =SUMPRODUCT(1/($B$169:$B$170^2+N24),$A$169:$A$170)/SUMPRODUCT(1/($B$169:$B$170^2+N24)) -> 0.052546887 | Q24: =SQRT(1/SUMPRODUCT(1/($B$169:$B$170^2+N24))) -> 0.10738597
A26: Very low birthweight <1500g | B26: 1. Semprini + Montoya + Sherris | C26: Semprini 2026 | D26: =J26 -> 1 | E26: =EXP(P26) -> 1.3828 | F26: =EXP(P26-1.959964*Q26) -> 1.0381158 | G26: =EXP(P26+1.959964*Q26) -> 1.8419292 | H26: =IF(J26>1,O26,"") | J26: 1 | K26: =SUMPRODUCT(1/$B$172:$B$172^2,$A$172:$A$172)/SUMPRODUCT(1/$B$172:$B$172^2) -> 0.32411043 | L26: =IF(J26>1,SUMPRODUCT(1/$B$172:$B$172^2,($A$172:$A$172-K26)^2),0) -> 0 | M26: =IF(J26>1,SUMPRODUCT(1/$B$172:$B$172^2)-SUMPRODUCT(1/$B$172:$B$172^2,1/$B$172:$B$172^2)/SUMPRODUCT(1/$B$172:$B$172^2),0) -> 0 | N26: =IF(M26>0,MAX(0,(L26-(J26-1))/M26),0) -> 0 | O26: =IF(AND(J26>1,L26>0),MAX(0,(L26-(J26-1))/L26),0) -> 0 | P26: =SUMPRODUCT(1/($B$172:$B$172^2+N26),$A$172:$A$172)/SUMPRODUCT(1/($B$172:$B$172^2+N26)) -> 0.32411043 | Q26: =SQRT(1/SUMPRODUCT(1/($B$172:$B$172^2+N26))) -> 0.14627977
A27: Very low birthweight <1500g | B27: 2. SR evidence base (Clemmensen) | C27: Stayner 2017 | D27: =J27 -> 1 | E27: =EXP(P27) -> 2.192448 | F27: =EXP(P27-1.959964*Q27) -> 1.5212958 | G27: =EXP(P27+1.959964*Q27) -> 3.1596935 | H27: =IF(J27>1,O27,"") | J27: 1 | K27: =SUMPRODUCT(1/$B$174:$B$174^2,$A$174:$A$174)/SUMPRODUCT(1/$B$174:$B$174^2) -> 0.78501874 | L27: =IF(J27>1,SUMPRODUCT(1/$B$174:$B$174^2,($A$174:$A$174-K27)^2),0) -> 0 | M27: =IF(J27>1,SUMPRODUCT(1/$B$174:$B$174^2)-SUMPRODUCT(1/$B$174:$B$174^2,1/$B$174:$B$174^2)/SUMPRODUCT(1/$B$174:$B$174^2),0) -> 0 | N27: =IF(M27>0,MAX(0,(L27-(J27-1))/M27),0) -> 0 | O27: =IF(AND(J27>1,L27>0),MAX(0,(L27-(J27-1))/L27),0) -> 0 | P27: =SUMPRODUCT(1/($B$174:$B$174^2+N27),$A$174:$A$174)/SUMPRODUCT(1/($B$174:$B$174^2+N27)) -> 0.78501874 | Q27: =SQRT(1/SUMPRODUCT(1/($B$174:$B$174^2+N27))) -> 0.18646071
A28: Very low birthweight <1500g | B28: 3. Semprini + SR | C28: Semprini 2026, Stayner 2017 | D28: =J28 -> 2 | E28: =EXP(P28) -> 1.7161112 | F28: =EXP(P28-1.959964*Q28) -> 1.0933806 | G28: =EXP(P28+1.959964*Q28) -> 2.6935156 | H28: =IF(J28>1,O28,"") -> 0.73561336 | J28: 2 | K28: =SUMPRODUCT(1/$B$176:$B$177^2,$A$176:$A$177)/SUMPRODUCT(1/$B$176:$B$177^2) -> 0.49970637 | L28: =IF(J28>1,SUMPRODUCT(1/$B$176:$B$177^2,($A$176:$A$177-K28)^2),0) -> 3.7823393 | M28: =IF(J28>1,SUMPRODUCT(1/$B$176:$B$177^2)-SUMPRODUCT(1/$B$176:$B$177^2,1/$B$176:$B$177^2)/SUMPRODUCT(1/$B$176:$B$177^2),0) -> 35.609133 | N28: =IF(M28>0,MAX(0,(L28-(J28-1))/M28),0) -> 0.078135554 | O28: =IF(AND(J28>1,L28>0),MAX(0,(L28-(J28-1))/L28),0) -> 0.73561336 | P28: =SUMPRODUCT(1/($B$176:$B$177^2+N28),$A$176:$A$177)/SUMPRODUCT(1/($B$176:$B$177^2+N28)) -> 0.54006081 | Q28: =SQRT(1/SUMPRODUCT(1/($B$176:$B$177^2+N28))) -> 0.2299973
A29: Very low birthweight <1500g | B29: 4. Montoya + SR | C29: Stayner 2017 | D29: =J29 -> 1 | E29: =EXP(P29) -> 2.192448 | F29: =EXP(P29-1.959964*Q29) -> 1.5212958 | G29: =EXP(P29+1.959964*Q29) -> 3.1596935 | H29: =IF(J29>1,O29,"") | J29: 1 | K29: =SUMPRODUCT(1/$B$179:$B$179^2,$A$179:$A$179)/SUMPRODUCT(1/$B$179:$B$179^2) -> 0.78501874 | L29: =IF(J29>1,SUMPRODUCT(1/$B$179:$B$179^2,($A$179:$A$179-K29)^2),0) -> 0 | M29: =IF(J29>1,SUMPRODUCT(1/$B$179:$B$179^2)-SUMPRODUCT(1/$B$179:$B$179^2,1/$B$179:$B$179^2)/SUMPRODUCT(1/$B$179:$B$179^2),0) -> 0 | N29: =IF(M29>0,MAX(0,(L29-(J29-1))/M29),0) -> 0 | O29: =IF(AND(J29>1,L29>0),MAX(0,(L29-(J29-1))/L29),0) -> 0 | P29: =SUMPRODUCT(1/($B$179:$B$179^2+N29),$A$179:$A$179)/SUMPRODUCT(1/($B$179:$B$179^2+N29)) -> 0.78501874 | Q29: =SQRT(1/SUMPRODUCT(1/($B$179:$B$179^2+N29))) -> 0.18646071
A30: Very low birthweight <1500g | B30: 5. Sherris + SR | C30: Stayner 2017 | D30: =J30 -> 1 | E30: =EXP(P30) -> 2.192448 | F30: =EXP(P30-1.959964*Q30) -> 1.5212958 | G30: =EXP(P30+1.959964*Q30) -> 3.1596935 | H30: =IF(J30>1,O30,"") | I30: Sherris is INSIDE the SR. SR set shown here excludes it to avoid double counting. | J30: 1 | K30: =SUMPRODUCT(1/$B$181:$B$181^2,$A$181:$A$181)/SUMPRODUCT(1/$B$181:$B$181^2) -> 0.78501874 | L30: =IF(J30>1,SUMPRODUCT(1/$B$181:$B$181^2,($A$181:$A$181-K30)^2),0) -> 0 | M30: =IF(J30>1,SUMPRODUCT(1/$B$181:$B$181^2)-SUMPRODUCT(1/$B$181:$B$181^2,1/$B$181:$B$181^2)/SUMPRODUCT(1/$B$181:$B$181^2),0) -> 0 | N30: =IF(M30>0,MAX(0,(L30-(J30-1))/M30),0) -> 0 | O30: =IF(AND(J30>1,L30>0),MAX(0,(L30-(J30-1))/L30),0) -> 0 | P30: =SUMPRODUCT(1/($B$181:$B$181^2+N30),$A$181:$A$181)/SUMPRODUCT(1/($B$181:$B$181^2+N30)) -> 0.78501874 | Q30: =SQRT(1/SUMPRODUCT(1/($B$181:$B$181^2+N30))) -> 0.18646071
A31: Very low birthweight <1500g | B31: 6. All studies combined | C31: Semprini 2026, Stayner 2017 | D31: =J31 -> 2 | E31: =EXP(P31) -> 1.7161112 | F31: =EXP(P31-1.959964*Q31) -> 1.0933806 | G31: =EXP(P31+1.959964*Q31) -> 2.6935156 | H31: =IF(J31>1,O31,"") -> 0.73561336 | J31: 2 | K31: =SUMPRODUCT(1/$B$183:$B$184^2,$A$183:$A$184)/SUMPRODUCT(1/$B$183:$B$184^2) -> 0.49970637 | L31: =IF(J31>1,SUMPRODUCT(1/$B$183:$B$184^2,($A$183:$A$184-K31)^2),0) -> 3.7823393 | M31: =IF(J31>1,SUMPRODUCT(1/$B$183:$B$184^2)-SUMPRODUCT(1/$B$183:$B$184^2,1/$B$183:$B$184^2)/SUMPRODUCT(1/$B$183:$B$184^2),0) -> 35.609133 | N31: =IF(M31>0,MAX(0,(L31-(J31-1))/M31),0) -> 0.078135554 | O31: =IF(AND(J31>1,L31>0),MAX(0,(L31-(J31-1))/L31),0) -> 0.73561336 | P31: =SUMPRODUCT(1/($B$183:$B$184^2+N31),$A$183:$A$184)/SUMPRODUCT(1/($B$183:$B$184^2+N31)) -> 0.54006081 | Q31: =SQRT(1/SUMPRODUCT(1/($B$183:$B$184^2+N31))) -> 0.2299973
A115: Helper ranges below: ln(multiplier at 5 mg/L-N) and its SE, pulled from the 'Study multipliers' sheet.
A120: ='Study multipliers'!O3 -> 0.12628017 | B120: ='Study multipliers'!P3 -> 0.046379545
A121: ='Study multipliers'!O5 -> 0.13976194 | B121: ='Study multipliers'!P5 -> 0.043584769
A122: ='Study multipliers'!O8 -> 0.076961041 | B122: ='Study multipliers'!P8 -> 0.030602428
A124: ='Study multipliers'!O10 -> 0.046988011 | B124: ='Study multipliers'!P10 -> 0.011869431
A125: ='Study multipliers'!O11 -> 0.043844102 | B125: ='Study multipliers'!P11 -> 0.016695411
A127: ='Study multipliers'!O3 -> 0.12628017 | B127: ='Study multipliers'!P3 -> 0.046379545
A128: ='Study multipliers'!O10 -> 0.046988011 | B128: ='Study multipliers'!P10 -> 0.011869431
A129: ='Study multipliers'!O11 -> 0.043844102 | B129: ='Study multipliers'!P11 -> 0.016695411
A131: ='Study multipliers'!O5 -> 0.13976194 | B131: ='Study multipliers'!P5 -> 0.043584769
A132: ='Study multipliers'!O10 -> 0.046988011 | B132: ='Study multipliers'!P10 -> 0.011869431
A133: ='Study multipliers'!O11 -> 0.043844102 | B133: ='Study multipliers'!P11 -> 0.016695411
A135: ='Study multipliers'!O8 -> 0.076961041 | B135: ='Study multipliers'!P8 -> 0.030602428
...

Sheet Three-study pool
A1: Semprini, Montoya and Sherris side by side
A2: The three studies you asked to pool. All three contrast roughly 5 to 10 mg/L nitrate-N against below 5, all three are large US administrative-data analyses, and all three were designed to isolate within-area or within-mother variation. That is an unusually well-matched set.
A4: Outcome | B4: Semprini 2026 (Iowa) | C4: Montoya 2025 (California) | D4: Sherris 2021 (California) | E4: Pooled | F4: 95% CI | G4: I^2
A5: Preterm <37wk | B5: =TEXT('Study multipliers'!N3,"0.00")&" ("&TEXT('Study multipliers'!K3,"0.00")&" to "&TEXT('Study multipliers'!L3,"0.00")&")" -> 1.13 (1.03 to 1.24) | C5: =TEXT('Study multipliers'!N5,"0.00")&" ("&TEXT('Study multipliers'!K5,"0.00")&" to "&TEXT('Study multipliers'!L5,"0.00")&")" -> 1.15 (1.05 to 1.25) | D5: =TEXT('Study multipliers'!N8,"0.00")&" ("&TEXT('Study multipliers'!K8,"0.00")&" to "&TEXT('Study multipliers'!L8,"0.00")&")" -> 1.08 (1.02 to 1.15) | E5: ='Pooled comparisons'!E5 -> 1.1097683 | F5: =TEXT('Pooled comparisons'!F5,"0.000")&" to "&TEXT('Pooled comparisons'!G5,"0.000") -> 1.063 to 1.159 | G5: ='Pooled comparisons'!H5 -> 0
A6: Very preterm <32wk | B6: =TEXT('Study multipliers'!N16,"0.00")&" ("&TEXT('Study multipliers'!K16,"0.00")&" to "&TEXT('Study multipliers'!L16,"0.00")&")" -> 1.46 (1.07 to 1.85) | C6: not reported | D6: =TEXT('Study multipliers'!N18,"0.00")&" ("&TEXT('Study multipliers'!K18,"0.00")&" to "&TEXT('Study multipliers'!L18,"0.00")&")" -> 1.47 (1.29 to 1.67) | E6: ='Pooled comparisons'!E12 -> 1.4684437 | F6: =TEXT('Pooled comparisons'!F12,"0.000")&" to "&TEXT('Pooled comparisons'!G12,"0.000") -> 1.306 to 1.650 | G6: ='Pooled comparisons'!H12 -> 0
A7: Low birthweight <2500g | B7: =TEXT('Study multipliers'!N27,"0.00")&" ("&TEXT('Study multipliers'!K27,"0.00")&" to "&TEXT('Study multipliers'!L27,"0.00")&")" -> 0.94 (0.82 to 1.06) | C7: =TEXT('Study multipliers'!N28,"0.00")&" ("&TEXT('Study multipliers'!K28,"0.00")&" to "&TEXT('Study multipliers'!L28,"0.00")&")" -> 1.17 (1.07 to 1.26) | D7: not reported | E7: ='Pooled comparisons'!E19 -> 1.053952 | F7: =TEXT('Pooled comparisons'!F19,"0.000")&" to "&TEXT('Pooled comparisons'!G19,"0.000") -> 0.854 to 1.301 | G7: ='Pooled comparisons'!H19 -> 0.86521703
A8: Very low birthweight <1500g | B8: =TEXT('Study multipliers'!N33,"0.00")&" ("&TEXT('Study multipliers'!K33,"0.00")&" to "&TEXT('Study multipliers'!L33,"0.00")&")" -> 1.38 (1.00 to 1.77) | C8: not reported | D8: not reported | E8: ='Pooled comparisons'!E26 -> 1.3828 | F8: =TEXT('Pooled comparisons'!F26,"0.000")&" to "&TEXT('Pooled comparisons'!G26,"0.000") -> 1.038 to 1.842 | G8: ='Pooled comparisons'!H26
A10: Sherris reports spontaneous preterm birth in two strata, 20-31 weeks and 32-36 weeks, not a single <37 week estimate. The 32-36 week figure is used in the 'Preterm <37wk' row because it covers the large majority of preterm births, and the 20-31 week figure in the 'Very preterm' row. This is a mapping, not an exact match, and it is the single biggest judgement call in this workbook.
A11: Semprini and Montoya report linear-probability marginal effects in percentage points. These are converted to multipliers as 1 + (effect / baseline rate), using each paper's own reported baseline. The conversion is exact for the point estimate and treats the confidence limits the same way.
A12: The very preterm result is the striking one: Semprini 1.46 in Iowa, Sherris 1.47 in California, and Stayner 1.47 across four Midwestern states once rescaled. Three designs, three populations, essentially one number, and zero measurable heterogeneity.
A13: Low birthweight is where the three disagree: Semprini is slightly below 1 and Montoya is clearly above it, with I-squared of 87%. Do not present low birthweight as a settled finding.

Sheet Scale and overlap
A1: Two things that change the answer
A3: A. The rescaling assumption
A4: Studies reporting a per-unit effect have to be stretched to the 5 mg/L-N contrast the categorical studies use. That is log-linear extrapolation - the same assumption that turns odds ratios of 1.14 into Picetti's 1.91 for gastric cancer. Here is exactly what it does to each estimate.
A6: Study | B6: Outcome | C6: Native estimate | D6: Native unit | E6: mg/L-N per unit | F6: Exponent applied | G6: Rescaled to 5 mg/L-N | H6: Change
A7: Huang 2018 | B7: Preterm <37wk | C7: ='Study multipliers'!J10 -> 1.02 | D7: OR per 9.33 ppm | E7: 2.1072 | F7: 2.3728 | G7: ='Study multipliers'!N10 -> 1.0481094 | H7: =G7/C7-1 -> 0.027558278
A8: Coffman 2022 | B8: Preterm <37wk | C8: ='Study multipliers'!J11 -> 1.02 | D8: OR per 10 mg/L NO3 | E8: 2.2583 | F8: 2.2141 | G8: ='Study multipliers'!N11 -> 1.0448195 | H8: =G8/C8-1 -> 0.024332801
A9: Stayner 2017 | B9: Very preterm <32wk | C9: ='Study multipliers'!J22 -> 1.08 | D9: RR per 1 mg/L N | E9: 1 | F9: 5 | G9: ='Study multipliers'!N22 -> 1.4693281 | H9: =G9/C9-1 -> 0.36048896
A10: Stayner 2017 | B10: Very low birthweight <1500g | C10: ='Study multipliers'!J34 -> 1.17 | D10: RR per 1 mg/L N | E10: 1 | F10: 5 | G10: ='Study multipliers'!N34 -> 2.192448 | H10: =G10/C10-1 -> 0.87388721
A11: Sherris-cont 2021 | B11: Preterm <37wk | C11: ='Study multipliers'!J12 -> 1.003 | D11: OR per 1 mg/L N | E11: 1 | F11: 5 | G11: ='Study multipliers'!N12 -> 1.0150903 | H11: =G11/C11-1 -> 0.012054108
A12: Sherris-cont 2021 | B12: Very preterm <32wk | C12: ='Study multipliers'!J23 -> 1.015 | D12: OR per 1 mg/L N | E12: 1 | F12: 5 | G12: ='Study multipliers'!N23 -> 1.077284 | H12: =G12/C12-1 -> 0.061363551
A14: Stayner's very-low-birthweight estimate more than doubles under this transformation, from 1.17 to 2.19. Treat the rescaled Stayner figures as illustrative only. The three-study pool does not depend on any rescaling - all three report a categorical 5-10 mg/L contrast directly.
A17: B. Sherris appears twice
A18: Sherris 2021 is one of the 13 studies in the Clemmensen review. Pooling 'Sherris' against 'the SR' therefore counts it on both sides unless the SR set is stripped of it first - the exact error the Cochrane protocol identified in Essien and Picetti. Row 5 of the 'Pooled comparisons' sheet uses the stripped SR set. For reference, the same comparison done naively is shown below.
A20: Comparison | B20: k | C20: Pooled multiplier | D20: 95% LCL | E20: 95% UCL | F20: I^2
A21: Naive: Sherris counted twice (itself + inside the SR) | B21: =J21 -> 3 | C21: =EXP(P21) -> 1.469943 | D21: =EXP(P21-1.959964*Q21) -> 1.3470246 | E21: =EXP(P21+1.959964*Q21) -> 1.6040779 | F21: =IF(J21>1,O21,"") -> 0 | J21: 3 | K21: =SUMPRODUCT(1/$U$200:$U$202^2,$T$200:$T$202)/SUMPRODUCT(1/$U$200:$U$202^2) -> 0.38522364 | L21: =IF(J21>1,SUMPRODUCT(1/$U$200:$U$202^2,($T$200:$T$202-K21)^2),0) -> 8.170961e-06 | M21: =IF(J21>1,SUMPRODUCT(1/$U$200:$U$202^2)-SUMPRODUCT(1/$U$200:$U$202^2,1/$U$200:$U$202^2)/SUMPRODUCT(1/$U$200:$U$202^2),0) -> 289.15433 | N21: =IF(M21>0,MAX(0,(L21-(J21-1))/M21),0) -> 0 | O21: =IF(AND(J21>1,L21>0),MAX(0,(L21-(J21-1))/L21),0) -> 0 | P21: =SUMPRODUCT(1/($U$200:$U$202^2+N21),$T$200:$T$202)/SUMPRODUCT(1/($U$200:$U$202^2+N21)) -> 0.38522364 | Q21: =SQRT(1/SUMPRODUCT(1/($U$200:$U$202^2+N21))) -> 0.044554622
A22: Corrected: Sherris stripped from the SR set | B22: =J22 -> 2 | C22: =EXP(P22) -> 1.4698949 | D22: =EXP(P22-1.959964*Q22) -> 1.3055424 | E22: =EXP(P22+1.959964*Q22) -> 1.6549376 | F22: =IF(J22>1,O22,"") -> 0 | J22: 2 | K22: =SUMPRODUCT(1/$U$204:$U$205^2,$T$204:$T$205)/SUMPRODUCT(1/$U$204:$U$205^2) -> 0.38519093 | L22: =IF(J22>1,SUMPRODUCT(1/$U$204:$U$205^2,($T$204:$T$205-K22)^2),0) -> 7.5323122e-06 | M22: =IF(J22>1,SUMPRODUCT(1/$U$204:$U$205^2)-SUMPRODUCT(1/$U$204:$U$205^2,1/$U$204:$U$205^2)/SUMPRODUCT(1/$U$204:$U$205^2),0) -> 72.070105 | N22: =IF(M22>0,MAX(0,(L22-(J22-1))/M22),0) -> 0 | O22: =IF(AND(J22>1,L22>0),MAX(0,(L22-(J22-1))/L22),0) -> 0 | P22: =SUMPRODUCT(1/($U$204:$U$205^2+N22),$T$204:$T$205)/SUMPRODUCT(1/($U$204:$U$205^2+N22)) -> 0.38519093 | Q22: =SQRT(1/SUMPRODUCT(1/($U$204:$U$205^2+N22))) -> 0.06049721
T200: ='Study multipliers'!O18 -> 0.3852624 | U200: ='Study multipliers'!P18 -> 0.065863814
T201: ='Study multipliers'!O22 -> 0.38480521 | U201: ='Study multipliers'!P22 -> 0.15301214
T202: ='Study multipliers'!O18 -> 0.3852624 | U202: ='Study multipliers'!P18 -> 0.065863814
T204: ='Study multipliers'!O18 -> 0.3852624 | U204: ='Study multipliers'!P18 -> 0.065863814
T205: ='Study multipliers'!O22 -> 0.38480521 | U205: ='Study multipliers'!P22 -> 0.15301214

Sheet Birth weight (grams)
A1: Continuous birth weight - not a multiplier
A2: Birth weight is measured in grams, so it has no relative-risk form and cannot be pooled with the multipliers. Reported here for completeness.
A4: Study | B4: Year | C4: Country | D4: Contrast | E4: Effect (g) | F4: 95% LCL | G4: 95% UCL | H4: Note
A5: Montoya | B5: 2025 | C5: USA (California) | D5: Any month 5-10 vs <5 mg/L N, trimester 2 | E5: -15.331 | F5: -28.057 | G5: -2.605 | H5: Table 2 Panel B IV; SE 6.493
A6: Coffman | B6: 2021 | C6: Denmark | D6: Per 25 mg/L NO3 | E6: -9.7 | F6: -14.6 | G6: -4.8 | H6: In SR; no association with term LBW
A8: Both point the same way: more nitrate, slightly lower birth weight. Montoya's 15 g is about 0.47% of mean birth weight.
