Workbook

Sheet Read me
A1: Nitrate in drinking water and cancer: study-level multipliers and pooled estimates
A2: Prepared for interview preparation. Compiled 2026-10-20.
A4: What a 'multiplier' means here
A5: The relative risk, odds ratio or hazard ratio a study reported for its highest drinking-water nitrate exposure group compared with its lowest. A multiplier of 1.20 means the most-exposed group had 20% higher odds or risk of that cancer than the least-exposed group in that study. These are associations from observational studies, not demonstrated causal effects.
A7: Sheets
A8: Study multipliers - every study-level estimate, grouped by cancer site, with two pooled rows per site. Columns V to AC hold the meta-analysis working (k, Q, tau-squared, I-squared, mu). Everything recalculates if you edit a multiplier or an inclusion flag.
A9: Pooled by cancer - the per-site answer, as published and de-duplicated, side by side, with what each published review reported for comparison.
A10: Per 10 mg per L - the same studies rescaled to a common dose increment. Read this against the previous sheet: the two scales disagree about which cancers are significant.
A11: All cancers pooled - the single overall multiplier, computed three ways, with a warning about why it should not be used.
A12: Iowa attributable fraction - what the pooled multipliers imply for Iowa case counts, with the exposed fraction as an editable input.
A14: Sources
A15: Study-level estimates were transcribed from Table 2 of Picetti et al. 2022, 'Nitrate and nitrite contamination in drinking water and cancer risk: a systematic review with meta-analysis', Environmental Research 210:112988, which is the most comprehensive table of drinking-water nitrate cancer studies available (60 cancer studies, 17 sites, PROSPERO CRD42020186945). Extraction was done by column coordinates from the published PDF rather than by reading converted text, to keep each estimate attached to the right study.
... A30: The direction of the pooled estimates is mildly positive almost everywhere, and the significance of individual sites flips depending on the scaling choice: on the highest-versus-lowest scale stomach and colorectal are both significantly elevated, while on the per 10 mg/L scale stomach loses significance and colorectal keeps it. Picetti, using a third approach, found the opposite pattern again. That instability across reasonable analytic choices is the substantive result, and it is the same point the Cochrane protocol makes about the existing reviews.

Sheet Study multipliers
A1: Cancer site | B1: Study | C1: Year | D1: Design | E1: Country | F1: Water source | G1: Exposure contrast | H1: Low (mg/L) | I1: High (mg/L) | J1: Metric | K1: Multiplier | L1: 95% LCL | M1: 95% UCL | N1: ln(mult) | O1: SE | P1: Inv-var weight | Q1: In pool: as published | R1: In pool: de-duplicated | S1: RE weight (as pub) | T1: RE weight (dedup) | U1: Notes | V1: k | W1: FE mean | X1: Q | Y1: C | Z1: tau^2 | AA1: I^2 | AB1: mu | AC1: SE(mu)
A2: Stomach
A3: Stomach | B3: Barrett | C3: 1998 | D3: Ecological | E3: UK | F3: Public | G3: Highest vs lowest quartile | H3: 2.4 | I3: 29.8 | J3: RR | K3: 0.96 | L3: 0.89 | M3: 1.05 | N3: =LN(K3) -> -0.040821995 | O3: =(LN(M3)-LN(L3))/(2*1.959964) -> 0.042175259 | P3: =IF(O3>0,1/O3^2,0) -> 562.19176 | Q3: 0 | R3: 0 | S3: =IF(Q3=1,1/(O3^2+$Z$14),0) -> 0 | T3: =IF(R3=1,1/(O3^2+$Z$15),0) -> 0 | U3: 15,544 cases
A4: Stomach | B4: Chiu | C4: 2012 | D4: Case-control | E4: Taiwan | F4: Municipal | G4: >=1.68 vs <1.68 | H4: 1.68 | I4: 1.68 | J4: OR | K4: 1.16 | L4: 1.05 | M4: 1.29 | N4: =LN(K4) -> 0.14842001 | O4: =(LN(M4)-LN(L4))/(2*1.959964) -> 0.052514244 | P4: =IF(O4>0,1/O4^2,0) -> 362.615 | Q4: 1 | R4: 1 | S4: =IF(Q4=1,1/(O4^2+$Z$14),0) -> 317.5955 | T4: =IF(R4=1,1/(O4^2+$Z$15),0) -> 362.615 | U4: 2832/2832
A5: Stomach | B5: Gulis | C5: 2002 | D5: Ecological | E5: Slovakia | F5: Municipal | G5: Highest tertile >20 | H5: 10 | I5: 20 | J5: SIR | K5: 1.08 | L5: 0.87 | M5: 1.35 | N5: =LN(K5) -> 0.076961041 | O5: =(LN(M5)-LN(L5))/(2*1.959964) -> 0.11208539 | P5: =IF(O5>0,1/O5^2,0) -> 79.597968 | Q5: 0 | R5: 0 | S5: =IF(Q5=1,1/(O5^2+$Z$14),0) -> 0 | T5: =IF(R5=1,1/(O5^2+$Z$15),0) -> 0 | U5: total
A6: Stomach | B6: Morales-Suarez-Varela | C6: 1995 | D6: Cross-sectional | E6: Spain | F6: Public | G6: >50 vs <25, men 55-75 | H6: 25 | I6: 50 | J6: RR | K6: 1.91 | L6: 1.36 | M6: 2.67 | N6: =LN(K6) -> 0.64710324 | O6: =(LN(M6)-LN(L6))/(2*1.959964) -> 0.17209341 | P6: =IF(O6>0,1/O6^2,0) -> 33.765371 | Q6: 0 | R6: 0 | S6: =IF(Q6=1,1/(O6^2+$Z$14),0) -> 0 | T6: =IF(R6=1,1/(O6^2+$Z$15),0) -> 0 | U6: age/sex stratum only
A7: Stomach | B7: Rademacher | C7: 1992 | D7: Case-control | E7: USA (WI) | F7: Public | G7: Highest quartile >44.22 | I7: 44.22 | J7: OR | K7: 1.5 | L7: 0.12 | M7: 18.25 | N7: =LN(K7) -> 0.40546511 | O7: =(LN(M7)-LN(L7))/(2*1.959964) -> 1.2817655 | P7: =IF(O7>0,1/O7^2,0) -> 0.60867129 | Q7: 1 | R7: 1 | S7: =IF(Q7=1,1/(O7^2+$Z$14),0) -> 0.6085265 | T7: =IF(R7=1,1/(O7^2+$Z$15),0) -> 0.60867129 | U7: excluded by Picetti: methods
A8: Stomach | B8: Taneja | C8: 2017 | D8: Case-control | E8: India | F8: Mixed | G8: Highest vs lowest | J8: OR | K8: 1.2 | L8: 1.04 | M8: 1.34 | N8: =LN(K8) -> 0.18232156 | O8: =(LN(M8)-LN(L8))/(2*1.959964) -> 0.064656519 | P8: =IF(O8>0,1/O8^2,0) -> 239.20781 | Q8: 1 | R8: 1 | S8: =IF(Q8=1,1/(O8^2+$Z$14),0) -> 218.75237 | T8: =IF(R8=1,1/(O8^2+$Z$15),0) -> 239.20781 | U8: 78/156
A9: Stomach | B9: van Loon | C9: 1997 | D9: Cohort | E9: Netherlands | F9: Municipal | G9: Higher vs lower quintile | J9: RR | K9: 1.02 | L9: 0.62 | M9: 1.68 | N9: =LN(K9) -> 0.019802627 | O9: =(LN(M9)-LN(L9))/(2*1.959964) -> 0.25429793 | P9: =IF(O9>0,1/O9^2,0) -> 15.463733 | Q9: 1 | R9: 1 | S9: =IF(Q9=1,1/(O9^2+$Z$14),0) -> 15.370816 | T9: =IF(R9=1,1/(O9^2+$Z$15),0) -> 15.463733 | U9: excluded by Picetti: units
A10: Stomach | B10: van Loon | C10: 1998 | D10: Cohort | E10: Netherlands | F10: Municipal | G10: Higher vs lower quintile (mg/d) | H10: 0.02 | I10: 16.5 | J10: RR | K10: 0.88 | L10: 0.59 | M10: 1.32 | N10: =LN(K10) -> -0.12783337 | O10: =(LN(M10)-LN(L10))/(2*1.959964) -> 0.20542839 | P10: =IF(O10>0,1/O10^2,0) -> 23.696221 | Q10: 1 | R10: 1 | S10: =IF(Q10=1,1/(O10^2+$Z$14),0) -> 23.478734 | T10: =IF(R10=1,1/(O10^2+$Z$15),0) -> 23.696221 | U10: excluded by Picetti: units
A11: Stomach | B11: Ward | C11: 2008 | D11: Case-control | E11: USA (NE) | F11: Public | G11: >19.11 vs <10.84 | H11: 10.84 | I11: 19.11 | J11: OR | K11: 1.2 | L11: 0.5 | M11: 2.7 | N11: =LN(K11) -> 0.18232156 | O11: =(LN(M11)-LN(L11))/(2*1.959964) -> 0.43021172 | P11: =IF(O11>0,1/O11^2,0) -> 5.403007 | Q11: 1 | R11: 1 | S11: =IF(Q11=1,1/(O11^2+$Z$14),0) -> 5.3916193 | T11: =IF(R11=1,1/(O11^2+$Z$15),0) -> 5.403007 | U11: 79 distal cases
A12: Stomach | B12: Yang | C12: 1997 | D12: Case-control | E12: Taiwan | F12: Municipal | G12: >=1.99 vs <=0.97 | H12: 0.97 | I12: 1.99 | J12: OR | K12: 1.02 | L12: 0.93 | M12: 1.11 | N12: =LN(K12) -> 0.019802627 | O12: =(LN(M12)-LN(L12))/(2*1.959964) -> 0.045136214 | P12: =IF(O12>0,1/O12^2,0) -> 490.85108 | Q12: 1 | R12: 0 | S12: =IF(Q12=1,1/(O12^2+$Z$14),0) -> 411.82917 | T12: =IF(R12=1,1/(O12^2+$Z$15),0) -> 0 | U12: superseded by Yang 1998
A13: Stomach | B13: Yang | C13: 1998 | D13: Case-control | E13: Taiwan | F13: Municipal | G13: >=1.99 vs <=0.97 | H13: 0.97 | I13: 1.99 | J13: OR | K13: 1.14 | L13: 1.04 | M13: 1.25 | N13: =LN(K13) -> 0.13102826 | O13: =(LN(M13)-LN(L13))/(2*1.959964) -> 0.046919953 | P13: =IF(O13>0,1/O13^2,0) -> 454.23946 | Q13: 1 | R13: 1 | S13: =IF(Q13=1,1/(O13^2+$Z$14),0) -> 385.74361 | T13: =IF(R13=1,1/(O13^2+$Z$15),0) -> 454.23946 | U13: 6766/6766
B14: POOLED - as published | J14: pooled | K14: =IF(V14>0,EXP(AB14),"") -> 1.1102928 | L14: =IF(V14>0,EXP(AB14-1.959964*AC14),"") -> 1.053207 | M14: =IF(V14>0,EXP(AB14+1.959964*AC14),"") -> 1.1704728 | V14: =SUM($Q$3:$Q$13) -> 8 | W14: =IF(V14>0,SUMPRODUCT($Q$3:$Q$13,$P$3:$P$13,$N$3:$N$13)/SUMPRODUCT($Q$3:$Q$13,$P$3:$P$13),0) -> 0.10375033 | X14: =IF(V14>1,SUMPRODUCT($Q$3:$Q$13,$P$3:$P$13,($N$3:$N$13-W14)^2),0) -> 7.4660083 | Y14: =IF(V14>1,SUMPRODUCT($Q$3:$Q$13,$P$3:$P$13)-SUMPRODUCT($Q$3:$Q$13,$P$3:$P$13,$P$3:$P$13)/SUMPRODUCT($Q$3:$Q$13,$P$3:$P$13),0) -> 1192.101 | Z14: =IF(Y14>0,MAX(0,(X14-(V14-1))/Y14),0) -> 0.00039091347 | AA14: =IF(AND(V14>1,X14>0),MAX(0,(X14-(V14-1))/X14),0) -> 0.062417334 | AB14: =IF(SUM($S$3:$S$13)>0,SUMPRODUCT($S$3:$S$13,$N$3:$N$13)/SUM($S$3:$S$13),0) -> 0.10462379 | AC14: =IF(SUM($S$3:$S$13)>0,SQRT(1/SUM($S$3:$S$13)),0) -> 0.026931096
B15: POOLED - de-duplicated | J15: pooled | K15: =IF(V15>0,EXP(AB15),"") -> 1.1516183 | L15: =IF(V15>0,EXP(AB15-1.959964*AC15),"") -> 1.0855711 | M15: =IF(V15>0,EXP(AB15+1.959964*AC15),"") -> 1.221684 | V15: =SUM($R$3:$R$13) -> 7 | W15: =IF(V15>0,SUMPRODUCT($R$3:$R$13,$P$3:$P$13,$N$3:$N$13)/SUMPRODUCT($R$3:$R$13,$P$3:$P$13),0) -> 0.14116819 | X15: =IF(V15>1,SUMPRODUCT($R$3:$R$13,$P$3:$P$13,($N$3:$N$13-W15)^2),0) -> 2.4650405 | Y15: =IF(V15>1,SUMPRODUCT($R$3:$R$13,$P$3:$P$13)-SUMPRODUCT($R$3:$R$13,$P$3:$P$13,$P$3:$P$13)/SUMPRODUCT($R$3:$R$13,$P$3:$P$13),0) -> 741.75196 | Z15: =IF(Y15>0,MAX(0,(X15-(V15-1))/Y15),0) -> 0 | AA15: =IF(AND(V15>1,X15>0),MAX(0,(X15-(V15-1))/X15),0) -> 0 | AB15: =IF(SUM($T$3:$T$13)>0,SUMPRODUCT($T$3:$T$13,$N$3:$N$13)/SUM($T$3:$T$13),0) -> 0.14116819 | AC15: =IF(SUM($T$3:$T$13)>0,SQRT(1/SUM($T$3:$T$13)),0) -> 0.030134238
A17: Esophagus
A18: Esophagus | B18: Barrett | C18: 1998 | D18: Ecological | E18: UK | F18: Public | G18: Highest vs lowest quartile | H18: 2.4 | I18: 29.8 | J18: RR | K18: 1.06 | L18: 0.98 | M18: 1.14 | N18: =LN(K18) -> 0.058268908 | O18: =(LN(M18)-LN(L18))/(2*1.959964) -> 0.038580038 | P18: =IF(O18>0,1/O18^2,0) -> 671.85369 | Q18: 0 | R18: 0 | S18: =IF(Q18=1,1/(O18^2+$Z$22),0) -> 0 | T18: =IF(R18=1,1/(O18^2+$Z$23),0) -> 0
A19: Esophagus | B19: Liao | C19: 2013 | D19: Case-control | E19: Taiwan | F19: Municipal | G19: >=2.92 vs <1.98 | H19: 1.98 | I19: 2.92 | J19: OR | K19: 1.05 | L19: 0.91 | M19: 1.19 | N19: =LN(K19) -> 0.048790164 | O19: =(LN(M19)-LN(L19))/(2*1.959964) -> 0.068435947 | P19: =IF(O19>0,1/O19^2,0) -> 213.5165 | Q19: 1 | R19: 1 | S19: =IF(Q19=1,1/(O19^2+$Z$22),0) -> 213.5165 | T19: =IF(R19=1,1/(O19^2+$Z$23),0) -> 213.5165 | U19: 3024/3024
A20: Esophagus | B20: Ward | C20: 2008 | D20: Case-control | E20: USA (NE) | F20: Public | G20: >19.11 vs <10.84 | H20: 10.84 | I20: 19.11 | J20: OR | K20: 1.2 | L20: 0.6 | M20: 2.7 | N20: =LN(K20) -> 0.18232156 | O20: =(LN(M20)-LN(L20))/(2*1.959964) -> 0.38370026 | P20: =IF(O20>0,1/O20^2,0) -> 6.7922836 | Q20: 1 | R20: 1 | S20: =IF(Q20=1,1/(O20^2+$Z$22),0) -> 6.7922836 | T20: =IF(R20=1,1/(O20^2+$Z$23),0) -> 6.7922836 | U20: 84 cases
A21: Esophagus | B21: Zhang | C21: 2012 | D21: Ecological | E21: China | F21: Wells/rivers | G21: Highest vs lowest | J21: OR | K21: 46.29 | L21: 3.16 | M21: 667.39 | N21: =LN(K21) -> 3.834926 | O21: =(LN(M21)-LN(L21))/(2*1.959964) -> 1.3655359 | P21: =IF(O21>0,1/O21^2,0) -> 0.53628263 | Q21: 0 | R21: 0 | S21: =IF(Q21=1,1/(O21^2+$Z$22),0) -> 0 | T21: =IF(R21=1,1/(O21^2+$Z$23),0) -> 0 | U21: extreme outlier
B22: POOLED - as published | J22: pooled | K22: =IF(V22>0,EXP(AB22),"") -> 1.0543316 | L22: =IF(V22>0,EXP(AB22-1.959964*AC22),"") -> 0.92390958 | M22: =IF(V22>0,EXP(AB22+1.959964*AC22),"") -> 1.2031645 | V22: =SUM($Q$18:$Q$21) -> 2 | W22: =IF(V22>0,SUMPRODUCT($Q$18:$Q$21,$P$18:$P$21,$N$18:$N$21)/SUMPRODUCT($Q$18:$Q$21,$P$18:$P$21),0) -> 0.052907036 | X22: =IF(V22>1,SUMPRODUCT($Q$18:$Q$21,$P$18:$P$21,($N$18:$N$21-W22)^2),0) -> 0.11737678 | Y22: =IF(V22>1,SUMPRODUCT($Q$18:$Q$21,$P$18:$P$21)-SUMPRODUCT($Q$18:$Q$21,$P$18:$P$21,$P$18:$P$21)/SUMPRODUCT($Q$18:$Q$21,$P$18:$P$21),0) -> 13.165745 | Z22: =IF(Y22>0,MAX(0,(X22-(V22-1))/Y22),0) -> 0 | AA22: =IF(AND(V22>1,X22>0),MAX(0,(X22-(V22-1))/X22),0) -> 0 | AB22: =IF(SUM($S$18:$S$21)>0,SUMPRODUCT($S$18:$S$21,$N$18:$N$21)/SUM($S$18:$S$21),0) -> 0.052907036 | AC22: =IF(SUM($S$18:$S$21)>0,SQRT(1/SUM($S$18:$S$21)),0) -> 0.067372723
B23: POOLED - de-duplicated | J23: pooled | K23: =IF(V23>0,EXP(AB23),"") -> 1.0543316 | L23: =IF(V23>0,EXP(AB23-1.959964*AC23),"") -> 0.92390958 | M23: =IF(V23>0,EXP(AB23+1.959964*AC23),"") -> 1.2031645 | V23: =SUM($R$18:$R$21) -> 2 | W23: =IF(V23>0,SUMPRODUCT($R$18:$R$21,$P$18:$P$21,$N$18:$N$21)/SUMPRODUCT($R$18:$R$21,$P$18:$P$21),0) -> 0.052907036 | X23: =IF(V23>1,SUMPRODUCT($R$18:$R$21,$P$18:$P$21,($N$18:$N$21-W23)^2),0) -> 0.11737678 | Y23: =IF(V23>1,SUMPRODUCT($R$18:$R$21,$P$18:$P$21)-SUMPRODUCT($R$18:$R$21,$P$18:$P$21,$P$18:$P$21)/SUMPRODUCT($R$18:$R$21,$P$18:$P$21),0) -> 13.165745 | Z23: =IF(Y23>0,MAX(0,(X23-(V23-1))/Y23),0) -> 0 | AA23: =IF(AND(V23>1,X23>0),MAX(0,(X23-(V23-1))/X23),0) -> 0 | AB23: =IF(SUM($T$18:$T$21)>0,SUMPRODUCT($T$18:$T$21,$N$18:$N$21)/SUM($T$18:$T$21),0) -> 0.052907036 | AC23: =IF(SUM($T$18:$T$21)>0,SQRT(1/SUM($T$18:$T$21)),0) -> 0.067372723
A25: Colorectal
A26: Colorectal | B26: Chang | C26: 2010 | D26: Case-control | E26: Taiwan | F26: Municipal | G26: >=1.68 vs <1.68 (rectal) | H26: 1.68 | I26: 1.68 | J26: OR | K26: 1.15 | L26: 1.01 | M26: 1.32 | N26: =LN(K26) -> 0.13976194 | O26: =(LN(M26)-LN(L26))/(2*1.959964) -> 0.068287327 | P26: =IF(O26>0,1/O26^2,0) -> 214.4469 | Q26: 1 | R26: 1 | S26: =IF(Q26=1,1/(O26^2+$Z$41),0) -> 96.355956 | T26: =IF(R26=1,1/(O26^2+$Z$42),0) -> 75.414224 | U26: rectal
A27: Colorectal | B27: Chiu | C27: 2010 | D27: Case-control | E27: Taiwan | F27: Municipal | G27: >2.67 vs <1.67 (colon) | H27: 1.67 | I27: 2.67 | J27: OR | K27: 1.16 | L27: 1.04 | M27: 1.3 | N27: =LN(K27) -> 0.14842001 | O27: =(LN(M27)-LN(L27))/(2*1.959964) -> 0.056925421 | P27: =IF(O27>0,1/O27^2,0) -> 308.59402 | Q27: 1 | R27: 1 | S27: =IF(Q27=1,1/(O27^2+$Z$41),0) -> 111.66285 | T27: =IF(R27=1,1/(O27^2+$Z$42),0) -> 84.477707 | U27: colon
A28: Colorectal | B28: Chiu | C28: 2011 | D28: Case-control | E28: Taiwan | F28: Municipal | G28: >=2.65 vs <1.68 (colon) | H28: 1.68 | I28: 2.65 | J28: OR | K28: 1.16 | L28: 1.04 | M28: 1.3 | N28: =LN(K28) -> 0.14842001 | O28: =(LN(M28)-LN(L28))/(2*1.959964) -> 0.056925421 | P28: =IF(O28>0,1/O28^2,0) -> 308.59402 | Q28: 1 | R28: 0 | S28: =IF(Q28=1,1/(O28^2+$Z$41),0) -> 111.66285 | T28: =IF(R28=1,1/(O28^2+$Z$42),0) -> 0 | U28: duplicate of Chiu 2010
A29: Colorectal | B29: De Roos | C29: 2003 | D29: Case-control | E29: USA (IA) | F29: Public | G29: >22.11 vs <=4.42 (colon) | H29: 4.42 | I29: 22.11 | J29: OR | K29: 1.2 | L29: 0.8 | M29: 1.7 | N29: =LN(K29) -> 0.18232156 | O29: =(LN(M29)-LN(L29))/(2*1.959964) -> 0.19229226 | P29: =IF(O29>0,1/O29^2,0) -> 27.044341 | Q29: 1 | R29: 1 | S29: =IF(Q29=1,1/(O29^2+$Z$41),0) -> 23.423955 | T29: =IF(R29=1,1/(O29^2+$Z$42),0) -> 21.942696 | U29: 376 colon cases
A30: Colorectal | B30: Espejo-Herrera | C30: 2016 | D30: Case-control | E30: Spain/Italy | F30: Municipal | G30: >10 vs <=5 mg/day (colon) | H30: 5 | I30: 10 | J30: OR | K30: 1.52 | L30: 1.24 | M30: 1.86 | N30: =LN(K30) -> 0.41871033 | O30: =(LN(M30)-LN(L30))/(2*1.959964) -> 0.10343688 | P30: =IF(O30>0,1/O30^2,0) -> 93.465042 | Q30: 1 | R30: 1 | S30: =IF(Q30=1,1/(O30^2+$Z$41),0) -> 60.922807 | T30: =IF(R30=1,1/(O30^2+$Z$42),0) -> 51.823873 | U30: colorectal CI misprinted; colon used
A31: Colorectal | B31: Fathmawati | C31: 2017 | D31: Case-control | E31: Indonesia | F31: Wells | G31: >50 vs <=50 | H31: 50 | I31: 50 | J31: OR | K31: 2.82 | L31: 1.075 | M31: 7.395 | N31: =LN(K31) -> 1.0367369 | O31: =(LN(M31)-LN(L31))/(2*1.959964) -> 0.4919691 | P31: =IF(O31>0,1/O31^2,0) -> 4.1316579 | Q31: 1 | R31: 1 | S31: =IF(Q31=1,1/(O31^2+$Z$41),0) -> 4.0363495 | T31: =IF(R31=1,1/(O31^2+$Z$42),0) -> 3.9899369 | U31: 75/75
A32: Colorectal | B32: Gulis | C32: 2002 | D32: Ecological | E32: Slovakia | F32: Municipal | G32: Highest tertile >20 | H32: 10 | I32: 20 | J32: SIR | K32: 1.18 | L32: 1.04 | M32: 1.34 | N32: =LN(K32) -> 0.16551444 | O32: =(LN(M32)-LN(L32))/(2*1.959964) -> 0.064656519 | P32: =IF(O32>0,1/O32^2,0) -> 239.20781 | Q32: 0 | R32: 0 | S32: =IF(Q32=1,1/(O32^2+$Z$41),0) -> 0 | T32: =IF(R32=1,1/(O32^2+$Z$42),0) -> 0 | U32: total
A33: Colorectal | B33: Jones | C33: 2019 | D33: Cohort | E33: USA (IA) | F33: Public | G33: >15.52 vs <1.59 (colon) | H33: 1.59 | I33: 15.52 | J33: HR | K33: 0.97 | L33: 0.75 | M33: 1.26 | N33: =LN(K33) -> -0.030459207 | O33: =(LN(M33)-LN(L33))/(2*1.959964) -> 0.13234779 | P33: =IF(O33>0,1/O33^2,0) -> 57.090867 | Q33: 1 | R33: 1 | S33: =IF(Q33=1,1/(O33^2+$Z$41),0) -> 43.045998 | T33: =IF(R33=1,1/(O33^2+$Z$42),0) -> 38.295285 | U33: 612 colon cases
A34: Colorectal | B34: Kuo | C34: 2007 | D34: Case-control | E34: Taiwan | F34: Municipal | G34: 2.12-12.60 vs <=0.49 (rectal) | H34: 0.49 | I34: 7.36 | J34: OR | K34: 1.36 | L34: 1.08 | M34: 1.7 | N34: =LN(K34) -> 0.3074847 | O34: =(LN(M34)-LN(L34))/(2*1.959964) -> 0.11573356 | P34: =IF(O34>0,1/O34^2,0) -> 74.658868 | Q34: 1 | R34: 1 | S34: =IF(Q34=1,1/(O34^2+$Z$41),0) -> 52.330588 | T34: =IF(R34=1,1/(O34^2+$Z$42),0) -> 45.472745 | U34: rectal
A35: Colorectal | B35: McElroy | C35: 2008 | D35: Case-control | E35: USA (WI) | F35: Private wells | G35: >=44.23 vs <2.21 | H35: 2.21 | I35: 44.23 | J35: OR | K35: 1.57 | L35: 0.97 | M35: 2.52 | N35: =LN(K35) -> 0.45107562 | O35: =(LN(M35)-LN(L35))/(2*1.959964) -> 0.24355501 | P35: =IF(O35>0,1/O35^2,0) -> 16.857993 | Q35: 1 | R35: 1 | S35: =IF(Q35=1,1/(O35^2+$Z$41),0) -> 15.376556 | T35: =IF(R35=1,1/(O35^2+$Z$42),0) -> 14.724075 | U35: 475/1447
A36: Colorectal | B36: Morales-Suarez-Varela | C36: 1995 | D36: Cross-sectional | E36: Spain | F36: Public | G36: >50 vs <25, women 55-75 | H36: 25 | I36: 50 | J36: RR | K36: 1.15 | L36: 0.57 | M36: 2.31 | N36: =LN(K36) -> 0.13976194 | O36: =(LN(M36)-LN(L36))/(2*1.959964) -> 0.35698779 | P36: =IF(O36>0,1/O36^2,0) -> 7.8468124 | Q36: 0 | R36: 0 | S36: =IF(Q36=1,1/(O36^2+$Z$41),0) -> 0 | T36: =IF(R36=1,1/(O36^2+$Z$42),0) -> 0 | U36: stratum only
A37: Colorectal | B37: Leclerc | C37: 1991 | D37: Cross-sectional | E37: France | F37: Municipal | G37: >45 vs <45 (GI+urinary) | H37: 45 | I37: 45 | J37: RR | K37: 0.94 | L37: 0.87 | M37: 1.02 | N37: =LN(K37) -> -0.061875404 | O37: =(LN(M37)-LN(L37))/(2*1.959964) -> 0.040578474 | P37: =IF(O37>0,1/O37^2,0) -> 607.30742 | Q37: 0 | R37: 0 | S37: =IF(Q37=1,1/(O37^2+$Z$41),0) -> 0 | T37: =IF(R37=1,1/(O37^2+$Z$42),0) -> 0 | U37: men; GI+urinary combined
... A40: Colorectal | B40: Yang | C40: 2007 | D40: Case-control | E40: Taiwan | F40: Municipal | G40: >=2.12 vs <=0.97 | H40: 0.97 | I40: 2.12 | J40: OR | K40: 0.98 | L40: 0.83 | M40: 1.16 | N40: =LN(K40) -> -0.020202707 | O40: =(LN(M40)-LN(L40))/(2*1.959964) -> 0.08539687 | P40: =IF(O40>0,1/O40^2,0) -> 137.12483 | Q40: 1 | R40: 1 | S40: =IF(Q40=1,1/(O40^2+$Z$41),0) -> 76.877825 | T40: =IF(R40=1,1/(O40^2+$Z$42),0) -> 62.934387 | U40: 2234/2234
B41: POOLED - as published | J41: pooled | K41: =IF(V41>0,EXP(AB41),"") -> 1.170151 | L41: =IF(V41>0,EXP(AB41-1.959964*AC41),"") -> 1.0898042 | M41: =IF(V41>0,EXP(AB41+1.959964*AC41),"") -> 1.2564215 | V41: =SUM($Q$26:$Q$40) -> 12 | W41: =IF(V41>0,SUMPRODUCT($Q$26:$Q$40,$P$26:$P$40,$N$26:$N$40)/SUMPRODUCT($Q$26:$Q$40,$P$26:$P$40),0) -> 0.14626209 | X41: =IF(V41>1,SUMPRODUCT($Q$26:$Q$40,$P$26:$P$40,($N$26:$N$40-W41)^2),0) -> 20.021153 | Y41: =IF(V41>1,SUMPRODUCT($Q$26:$Q$40,$P$26:$P$40)-SUMPRODUCT($Q$26:$Q$40,$P$26:$P$40,$P$26:$P$40)/SUMPRODUCT($Q$26:$Q$40,$P$26:$P$40),0) -> 1578.497 | Z41: =IF(Y41>0,MAX(0,(X41-(V41-1))/Y41),0) -> 0.0057150266 | AA41: =IF(AND(V41>1,X41>0),MAX(0,(X41-(V41-1))/X41),0) -> 0.45058108 | AB41: =IF(SUM($S$26:$S$40)>0,SUMPRODUCT($S$26:$S$40,$N$26:$N$40)/SUM($S$26:$S$40),0) -> 0.1571328 | AC41: =IF(SUM($S$26:$S$40)>0,SQRT(1/SUM($S$26:$S$40)),0) -> 0.036293922
B42: POOLED - de-duplicated | J42: pooled | K42: =IF(V42>0,EXP(AB42),"") -> 1.1838201 | L42: =IF(V42>0,EXP(AB42-1.959964*AC42),"") -> 1.0843501 | M42: =IF(V42>0,EXP(AB42+1.959964*AC42),"") -> 1.2924146 | V42: =SUM($R$26:$R$40) -> 10 | W42: =IF(V42>0,SUMPRODUCT($R$26:$R$40,$P$26:$P$40,$N$26:$N$40)/SUMPRODUCT($R$26:$R$40,$P$26:$P$40),0) -> 0.14814824 | X42: =IF(V42>1,SUMPRODUCT($R$26:$R$40,$P$26:$P$40,($N$26:$N$40-W42)^2),0) -> 19.504608 | Y42: =IF(V42>1,SUMPRODUCT($R$26:$R$40,$P$26:$P$40)-SUMPRODUCT($R$26:$R$40,$P$26:$P$40,$P$26:$P$40)/SUMPRODUCT($R$26:$R$40,$P$26:$P$40),0) -> 1221.901 | Z42: =IF(Y42>0,MAX(0,(X42-(V42-1))/Y42),0) -> 0.008596939 | AA42: =IF(AND(V42>1,X42>0),MAX(0,(X42-(V42-1))/X42),0) -> 0.53857058 | AB42: =IF(SUM($T$26:$T$40)>0,SUMPRODUCT($T$26:$T$40,$N$26:$N$40)/SUM($T$26:$T$40),0) -> 0.16874656 | AC42: =IF(SUM($T$26:$T$40)>0,SQRT(1/SUM($T$26:$T$40)),0) -> 0.044779253
A44: Pancreas
A45: Pancreas | B45: Coss | C45: 2004 | D45: Case-control | E45: USA (IA) | F45: Public | G45: >12.38 vs <2.65 | H45: 2.65 | I45: 12.38 | J45: OR | K45: 0.99 | L45: 0.64 | M45: 1.5 | N45: =LN(K45) -> -0.010050336 | O45: =(LN(M45)-LN(L45))/(2*1.959964) -> 0.21728772 | P45: =IF(O45>0,1/O45^2,0) -> 21.18018 | Q45: 1 | R45: 1 | S45: =IF(Q45=1,1/(O45^2+$Z$49),0) -> 20.73643 | T45: =IF(R45=1,1/(O45^2+$Z$50),0) -> 21.18018 | U45: 189/1244
...

Sheet Pooled by cancer
A1: Cancer site | B1: k | C1: Pooled multiplier | D1: 95% LCL | E1: 95% UCL | F1: I^2 | G1: k | H1: Pooled multiplier | I1: 95% LCL | J1: 95% UCL | K1: I^2 | L1: Verdict after de-duplication | M1: What the published reviews report
A2: Stomach | B2: ='Study multipliers'!V14 -> 8 | C2: ='Study multipliers'!K14 -> 1.1102928 | D2: ='Study multipliers'!L14 -> 1.053207 | E2: ='Study multipliers'!M14 -> 1.1704728 | F2: ='Study multipliers'!AA14 -> 0.062417334 | G2: ='Study multipliers'!V15 -> 7 | H2: ='Study multipliers'!K15 -> 1.1516183 | I2: ='Study multipliers'!L15 -> 1.0855711 | J2: ='Study multipliers'!M15 -> 1.221684 | K2: ='Study multipliers'!AA15 -> 0 | L2: =IF(G2=0,"no analytic studies",IF(I2>1,"Elevated",IF(J2<1,"Protective","Not significant"))) -> Elevated | M2: Picetti: RR 1.91 (1.09-3.33) per 10 mg/L, 4 case-control studies, I2 77%. Essien: OR 1.09 (0.97-1.21) high vs low, not significant.
A3: Esophagus | B3: ='Study multipliers'!V22 -> 2 | C3: ='Study multipliers'!K22 -> 1.0543316 | D3: ='Study multipliers'!L22 -> 0.92390958 | E3: ='Study multipliers'!M22 -> 1.2031645 | F3: ='Study multipliers'!AA22 -> 0 | G3: ='Study multipliers'!V23 -> 2 | H3: ='Study multipliers'!K23 -> 1.0543316 | I3: ='Study multipliers'!L23 -> 0.92390958 | J3: ='Study multipliers'!M23 -> 1.2031645 | K3: ='Study multipliers'!AA23 -> 0 | L3: =IF(G3=0,"no analytic studies",IF(I3>1,"Elevated",IF(J3<1,"Protective","Not significant"))) -> Not significant | M3: Picetti: RR 1.08 (0.85-1.37). Essien: OR 1.06 (0.99-1.13).
A4: Colorectal | B4: ='Study multipliers'!V41 -> 12 | C4: ='Study multipliers'!K41 -> 1.170151 | D4: ='Study multipliers'!L41 -> 1.0898042 | E4: ='Study multipliers'!M41 -> 1.2564215 | F4: ='Study multipliers'!AA41 -> 0.45058108 | G4: ='Study multipliers'!V42 -> 10 | H4: ='Study multipliers'!K42 -> 1.1838201 | I4: ='Study multipliers'!L42 -> 1.0843501 | J4: ='Study multipliers'!M42 -> 1.2924146 | K4: ='Study multipliers'!AA42 -> 0.53857058 | L4: =IF(G4=0,"no analytic studies",IF(I4>1,"Elevated",IF(J4<1,"Protective","Not significant"))) -> Elevated | M4: Picetti: RR 1.052 (0.995-1.111) per 10 mg/L, not significant. Essien colon: OR 1.11 (1.04-1.17). Temkin: RR 1.04 (1.01-1.07) per 1 mg/L nitrate-N.
A5: Pancreas | B5: ='Study multipliers'!V49 -> 4 | C5: ='Study multipliers'!K49 -> 1.0684482 | D5: ='Study multipliers'!L49 -> 0.92866969 | E5: ='Study multipliers'!M49 -> 1.2292655 | F5: ='Study multipliers'!AA49 -> 0.019016335 | G5: ='Study multipliers'!V50 -> 3 | H5: ='Study multipliers'!K50 -> 1.0910229 | I5: ='Study multipliers'!L50 -> 0.95686583 | J5: ='Study multipliers'!M50 -> 1.2439894 | K5: ='Study multipliers'!AA50 -> 0 | L5: =IF(G5=0,"no analytic studies",IF(I5>1,"Elevated",IF(J5<1,"Protective","Not significant"))) -> Not significant | M5: Picetti: no significant association. Essien: OR 1.08 (0.94-1.22).
A6: Bladder | B6: ='Study multipliers'!V60 -> 7 | C6: ='Study multipliers'!K60 -> 1.2364988 | D6: ='Study multipliers'!L60 -> 0.83475917 | E6: ='Study multipliers'!M60 -> 1.8315813 | F6: ='Study multipliers'!AA60 -> 0.84251964 | G6: ='Study multipliers'!V61 -> 6 | H6: ='Study multipliers'!K61 -> 1.1523387 | I6: ='Study multipliers'!L61 -> 0.76496472 | J6: ='Study multipliers'!M61 -> 1.7358769 | K6: ='Study multipliers'!AA61 -> 0.85812965 | L6: =IF(G6=0,"no analytic studies",IF(I6>1,"Elevated",IF(J6<1,"Protective","Not significant"))) -> Not significant | M6: Picetti cohort-only: RR 1.31 (1.03-1.66); case-control and combined analyses null. Essien: OR 0.94 (0.70-1.17).
A7: Kidney | B7: ='Study multipliers'!V68 -> 4 | C7: ='Study multipliers'!K68 -> 1.1895575 | D7: ='Study multipliers'!L68 -> 0.72080252 | E7: ='Study multipliers'!M68 -> 1.9631551 | F7: ='Study multipliers'!AA68 -> 0.51392439 | G7: ='Study multipliers'!V69 -> 3 | H7: ='Study multipliers'!K69 -> 1.2242959 | I7: ='Study multipliers'!L69 -> 0.63474216 | J7: ='Study multipliers'!M69 -> 2.3614321 | K7: ='Study multipliers'!AA69 -> 0.6741692 | L7: =IF(G7=0,"no analytic studies",IF(I7>1,"Elevated",IF(J7<1,"Protective","Not significant"))) -> Not significant | M7: Picetti: no significant association. Essien: OR 1.03 (0.78-1.28).
A8: Brain | B8: ='Study multipliers'!V81 -> 7 | C8: ='Study multipliers'!K81 -> 1.12498 | D8: ='Study multipliers'!L81 -> 0.95696104 | E8: ='Study multipliers'!M81 -> 1.322499 | F8: ='Study multipliers'!AA81 -> 0.067009314 | G8: ='Study multipliers'!V82 -> 7 | H8: ='Study multipliers'!K82 -> 1.12498 | I8: ='Study multipliers'!L82 -> 0.95696104 | J8: ='Study multipliers'!M82 -> 1.322499 | K8: ='Study multipliers'!AA82 -> 0.067009314 | L8: =IF(G8=0,"no analytic studies",IF(I8>1,"Elevated",IF(J8<1,"Protective","Not significant"))) -> Not significant | M8: Picetti: no significant association. Essien brain/glioma: OR 1.15 (1.06-1.24).
A9: Non-Hodgkin lymphoma | B9: ='Study multipliers'!V95 -> 6 | C9: ='Study multipliers'!K95 -> 0.92580896 | D9: ='Study multipliers'!L95 -> 0.63888678 | E9: ='Study multipliers'!M95 -> 1.3415871 | F9: ='Study multipliers'!AA95 -> 0.64465961 | G9: ='Study multipliers'!V96 -> 6 | H9: ='Study multipliers'!K96 -> 0.92580896 | I9: ='Study multipliers'!L96 -> 0.63888678 | J9: ='Study multipliers'!M96 -> 1.3415871 | K9: ='Study multipliers'!AA96 -> 0.64465961 | L9: =IF(G9=0,"no analytic studies",IF(I9>1,"Elevated",IF(J9<1,"Protective","Not significant"))) -> Not significant | M9: Picetti: no significant association. Essien: OR 0.98 (0.81-1.16).
A10: Breast | B10: ='Study multipliers'!V102 -> 3 | C10: ='Study multipliers'!K102 -> 1.0163743 | D10: ='Study multipliers'!L102 -> 0.86573413 | E10: ='Study multipliers'!M102 -> 1.1932264 | F10: ='Study multipliers'!AA102 -> 0 | G10: ='Study multipliers'!V103 -> 3 | H10: ='Study multipliers'!K103 -> 1.0163743 | I10: ='Study multipliers'!L103 -> 0.86573413 | J10: ='Study multipliers'!M103 -> 1.1932264 | K10: ='Study multipliers'!AA103 -> 0 | L10: =IF(G10=0,"no analytic studies",IF(I10>1,"Elevated",IF(J10<1,"Protective","Not significant"))) -> Not significant | M10: Picetti: meta-analysis not performed (different exposure types). Essien: OR 1.06 (0.94-1.19).
A11: Leukemia | B11: ='Study multipliers'!V109 -> 2 | C11: ='Study multipliers'!K109 -> 0.84577792 | D11: ='Study multipliers'!L109 -> 0.52058421 | E11: ='Study multipliers'!M109 -> 1.3741106 | F11: ='Study multipliers'!AA109 -> 0 | G11: ='Study multipliers'!V110 -> 2 | H11: ='Study multipliers'!K110 -> 0.84577792 | I11: ='Study multipliers'!L110 -> 0.52058421 | J11: ='Study multipliers'!M110 -> 1.3741106 | K11: ='Study multipliers'!AA110 -> 0 | L11: =IF(G11=0,"no analytic studies",IF(I11>1,"Elevated",IF(J11<1,"Protective","Not significant"))) -> Not significant | M11: Picetti: too few studies to pool.
A12: Ovary | B12: ='Study multipliers'!V115 -> 2 | C12: ='Study multipliers'!K115 -> 2.1018746 | D12: ='Study multipliers'!L115 -> 1.3994968 | E12: ='Study multipliers'!M115 -> 3.1567611 | F12: ='Study multipliers'!AA115 -> 0 | G12: ='Study multipliers'!V116 -> 1 | H12: ='Study multipliers'!K116 -> 2.14 | I12: ='Study multipliers'!L116 -> 1.2968323 | J12: ='Study multipliers'!M116 -> 3.5313741 | K12: ='Study multipliers'!AA116 -> 0 | L12: =IF(G12=0,"no analytic studies",IF(I12>1,"Elevated",IF(J12<1,"Protective","Not significant"))) -> Elevated | M12: Picetti: not significant per 10 mg/L. Both studies are the same Iowa cohort.
A13: Uterus | B13: ='Study multipliers'!V120 -> 1 | C13: ='Study multipliers'!K120 -> 0.65 | D13: ='Study multipliers'!L120 -> 0.39929183 | E13: ='Study multipliers'!M120 -> 1.0581233 | F13: ='Study multipliers'!AA120 -> 0 | G13: ='Study multipliers'!V121 -> 1 | H13: ='Study multipliers'!K121 -> 0.65 | I13: ='Study multipliers'!L121 -> 0.39929183 | J13: ='Study multipliers'!M121 -> 1.0581233 | K13: ='Study multipliers'!AA121 -> 0 | L13: =IF(G13=0,"no analytic studies",IF(I13>1,"Elevated",IF(J13<1,"Protective","Not significant"))) -> Not significant | M13: Single study (Iowa Women's Health Study).
A14: Prostate | B14: ='Study multipliers'!V126 -> 1 | C14: ='Study multipliers'!K126 -> 1.06 | D14: ='Study multipliers'!L126 -> 0.75959449 | E14: ='Study multipliers'!M126 -> 1.4792103 | F14: ='Study multipliers'!AA126 -> 0 | G14: ='Study multipliers'!V127 -> 1 | H14: ='Study multipliers'!K127 -> 1.06 | I14: ='Study multipliers'!L127 -> 0.75959449 | J14: ='Study multipliers'!M127 -> 1.4792103 | K14: ='Study multipliers'!AA127 -> 0 | L14: =IF(G14=0,"no analytic studies",IF(I14>1,"Elevated",IF(J14<1,"Protective","Not significant"))) -> Not significant | M14: No meta-analysis in any review. Essien: prostate not in the evidence base at all.
A15: Thyroid | B15: ='Study multipliers'!V131 -> 1 | C15: ='Study multipliers'!K131 -> 2.18 | D15: ='Study multipliers'!L131 -> 0.82753105 | E15: ='Study multipliers'!M131 -> 5.7428661 | F15: ='Study multipliers'!AA131 -> 0 | G15: ='Study multipliers'!V132 -> 1 | H15: ='Study multipliers'!K132 -> 2.18 | I15: ='Study multipliers'!L132 -> 0.82753105 | J15: ='Study multipliers'!M132 -> 5.7428661 | K15: ='Study multipliers'!AA132 -> 0 | L15: =IF(G15=0,"no analytic studies",IF(I15>1,"Elevated",IF(J15<1,"Protective","Not significant"))) -> Not significant | M15: No meta-analysis in any review. EPA review: 3 studies, 1 of medium confidence.
A16: Lung | B16: ='Study multipliers'!V136 -> 1 | C16: ='Study multipliers'!K136 -> 0.83 | D16: ='Study multipliers'!L136 -> 0.5483706 | E16: ='Study multipliers'!M136 -> 1.2562672 | F16: ='Study multipliers'!AA136 -> 0 | G16: ='Study multipliers'!V137 -> 1 | H16: ='Study multipliers'!K137 -> 0.83 | I16: ='Study multipliers'!L137 -> 0.5483706 | J16: ='Study multipliers'!M137 -> 1.2562672 | K16: ='Study multipliers'!AA137 -> 0 | L16: =IF(G16=0,"no analytic studies",IF(I16>1,"Elevated",IF(J16<1,"Protective","Not significant"))) -> Not significant | M16: EPA systematic review: 3 studies, zero of medium confidence or better.
A17: Melanoma | B17: ='Study multipliers'!V141 -> 1 | C17: ='Study multipliers'!K141 -> 0.92 | D17: ='Study multipliers'!L141 -> 0.59302044 | E17: ='Study multipliers'!M141 -> 1.4272695 | F17: ='Study multipliers'!AA141 -> 0 | G17: ='Study multipliers'!V142 -> 1 | H17: ='Study multipliers'!K142 -> 0.92 | I17: ='Study multipliers'!L142 -> 0.59302044 | J17: ='Study multipliers'!M142 -> 1.4272695 | K17: ='Study multipliers'!AA142 -> 0 | L17: =IF(G17=0,"no analytic studies",IF(I17>1,"Elevated",IF(J17<1,"Protective","Not significant"))) -> Not significant | M17: No drinking-water nitrate meta-analysis exists for melanoma.
A18: Urinary tract | B18: ='Study multipliers'!V146 -> 1 | C18: ='Study multipliers'!K146 -> 1.98 | D18: ='Study multipliers'!L146 -> 1.1037225 | E18: ='Study multipliers'!M146 -> 3.5519797 | F18: ='Study multipliers'!AA146 -> 0 | G18: ='Study multipliers'!V147 -> 1 | H18: ='Study multipliers'!K147 -> 1.98 | I18: ='Study multipliers'!L147 -> 1.1037225 | J18: ='Study multipliers'!M147 -> 3.5519797 | K18: ='Study multipliers'!AA147 -> 0 | L18: =IF(G18=0,"no analytic studies",IF(I18>1,"Elevated",IF(J18<1,"Protective","Not significant"))) -> Elevated | M18: Single study (Volkmer 2005, Germany).
A19: Other digestive | B19: ='Study multipliers'!V152 -> 1 | C19: ='Study multipliers'!K152 -> 1.7 | D19: ='Study multipliers'!L152 -> 0.74241873 | E19: ='Study multipliers'!M152 -> 3.892682 | F19: ='Study multipliers'!AA152 -> 0 | G19: ='Study multipliers'!V153 -> 1 | H19: ='Study multipliers'!K153 -> 1.7 | I19: ='Study multipliers'!L153 -> 0.74241873 | J19: ='Study multipliers'!M153 -> 3.892682 | K19: ='Study multipliers'!AA153 -> 0 | L19: =IF(G19=0,"no analytic studies",IF(I19>1,"Elevated",IF(J19<1,"Protective","Not significant"))) -> Not significant | M19: Not separately pooled in the published reviews.
A20: Bone | B20: ='Study multipliers'!V157 -> 0 | C20: ='Study multipliers'!K157 | D20: ='Study multipliers'!L157 | E20: ='Study multipliers'!M157 | F20: ='Study multipliers'!AA157 -> 0 | G20: ='Study multipliers'!V158 -> 0 | H20: ='Study multipliers'!K158 | I20: ='Study multipliers'!L158 | J20: ='Study multipliers'!M158 | K20: ='Study multipliers'!AA158 -> 0 | L20: =IF(G20=0,"no analytic studies",IF(I20>1,"Elevated",IF(J20<1,"Protective","Not significant"))) -> no analytic studies | M20: Single ecological study.
A21: All cancers combined | B21: ='Study multipliers'!V162 -> 0 | C21: ='Study multipliers'!K162 | D21: ='Study multipliers'!L162 | E21: ='Study multipliers'!M162 | F21: ='Study multipliers'!AA162 -> 0 | G21: ='Study multipliers'!V163 -> 0 | H21: ='Study multipliers'!K163 | I21: ='Study multipliers'!L163 | J21: ='Study multipliers'!M163 | K21: ='Study multipliers'!AA163 -> 0 | L21: =IF(G21=0,"no analytic studies",IF(I21>1,"Elevated",IF(J21<1,"Protective","Not significant"))) -> no analytic studies | M21: Single ecological study (Gulis 2002).
A23: Pooled with DerSimonian-Laird random effects on the log scale, using each study's highest-versus-lowest exposure contrast exactly as that study reported it.
A24: 'De-duplicated' keeps one estimate per independent population per cancer site. It drops Chiu 2011 (same cases and controls as Chiu 2010), Yang 1997 (superseded by Yang 1998), and the Weyer 2001 estimate at any site where a later Iowa Women's Health Study analysis covers the same cohort.
A25: Ecological and cross-sectional studies are excluded from both pools, following the approach the Cochrane protocol (CD015822) sets out. They remain on the 'Study multipliers' sheet with an inclusion flag of 0.
A26: CAUTION: a highest-versus-lowest pool is scale-free. 'Highest' means above 1.68 mg/L in the Taiwanese studies and above 44 mg/L in McElroy. These multipliers answer 'is the top exposure group at higher risk than the bottom group', not 'how much risk per unit of nitrate'. See the 'Per 10 mg per L' sheet for the dose-standardised version, which gives materially different answers.

Sheet Per 10 mg per L
A1: Dose-standardised multipliers: risk per 10 mg/L of nitrate
A2: Each study's highest-versus-lowest estimate is rescaled to a common 10 mg/L increment by assuming a linear increase in log-odds across the exposure range, the same assumption Picetti et al. used. Studies whose exposure categories share a boundary (for example '>=1.68 vs <1.68') have no defined contrast width and are excluded. De-duplicated set only.
A4: Cancer site | B4: Study | C4: Year | D4: Contrast width (mg/L) | E4: Multiplier as reported | F4: ln per 10 mg/L | G4: SE per 10 mg/L | H4: In pool | I4: RE weight | J4: Pooled multiplier | K4: 95% LCL | L4: 95% UCL | M4: I^2 | N4: k | O4: FE | P4: Q | Q4: C | R4: tau^2 | S4: mu | T4: SE(mu)
A5: Stomach
A6: Stomach | B6: Rademacher | C6: 1992 | D6: ='Study multipliers'!I7-'Study multipliers'!H7 -> 44.22 | E6: ='Study multipliers'!K7 -> 1.5 | F6: ='Study multipliers'!N7*10/D6 -> 0.091692697 | G6: ='Study multipliers'!O7*10/D6 -> 0.28986104 | H6: 1 | I6: =IF(H6=1,1/(G6^2+$R$10),0) -> 4.111592
A7: Stomach | B7: van Loon | C7: 1998 | D7: ='Study multipliers'!I10-'Study multipliers'!H10 -> 16.48 | E7: ='Study multipliers'!K10 -> 0.88 | F7: ='Study multipliers'!N10*10/D7 -> -0.077568793 | G7: ='Study multipliers'!O10*10/D7 -> 0.12465315 | H7: 1 | I7: =IF(H7=1,1/(G7^2+$R$10),0) -> 5.722992
A8: Stomach | B8: Ward | C8: 2008 | D8: ='Study multipliers'!I11-'Study multipliers'!H11 -> 8.27 | E8: ='Study multipliers'!K11 -> 1.2 | F8: ='Study multipliers'!N11*10/D8 -> 0.22046137 | G8: ='Study multipliers'!O11*10/D8 -> 0.52020764 | H8: 1 | I8: =IF(H8=1,1/(G8^2+$R$10),0) -> 2.3266021
A9: Stomach | B9: Yang | C9: 1998 | D9: ='Study multipliers'!I13-'Study multipliers'!H13 -> 1.02 | E9: ='Study multipliers'!K13 -> 1.14 | F9: ='Study multipliers'!N13*10/D9 -> 1.2845908 | G9: ='Study multipliers'!O13*10/D9 -> 0.45999954 | H9: 1 | I9: =IF(H9=1,1/(G9^2+$R$10),0) -> 2.6969084
B10: POOLED per 10 mg/L | J10: =EXP(S10) -> 1.3010673 | K10: =EXP(S10-1.959964*T10) -> 0.78248037 | L10: =EXP(S10+1.959964*T10) -> 2.1633466 | M10: =IF(AND(N10>1,P10>0),MAX(0,(P10-(N10-1))/P10),0) -> 0.6411594 | N10: =SUM($H$6:$H$9) -> 4 | O10: =SUMPRODUCT($H$6:$H$9,1/$G$6:$G$9^2,$F$6:$F$9)/SUMPRODUCT($H$6:$H$9,1/$G$6:$G$9^2) -> 0.035247828 | P10: =IF(N10>1,SUMPRODUCT($H$6:$H$9,1/$G$6:$G$9^2,($F$6:$F$9-O10)^2),0) -> 8.3602579 | Q10: =IF(N10>1,SUMPRODUCT($H$6:$H$9,1/$G$6:$G$9^2)-SUMPRODUCT($H$6:$H$9,1/$G$6:$G$9^2,1/$G$6:$G$9^2)/SUMPRODUCT($H$6:$H$9,1/$G$6:$G$9^2),0) -> 33.670941 | R10: =IF(Q10>0,MAX(0,(P10-(N10-1))/Q10),0) -> 0.15919537 | S10: =SUMPRODUCT($I$6:$I$9,$F$6:$F$9)/SUM($I$6:$I$9) -> 0.26318496 | T10: =SQRT(1/SUM($I$6:$I$9)) -> 0.25942895
A12: Esophagus
A13: Esophagus | B13: Liao | C13: 2013 | D13: ='Study multipliers'!I19-'Study multipliers'!H19 -> 0.94 | E13: ='Study multipliers'!K19 -> 1.05 | F13: ='Study multipliers'!N19*10/D13 -> 0.5190443 | G13: ='Study multipliers'!O19*10/D13 -> 0.72804199 | H13: 1 | I13: =IF(H13=1,1/(G13^2+$R$15),0) -> 1.8866318
A14: Esophagus | B14: Ward | C14: 2008 | D14: ='Study multipliers'!I20-'Study multipliers'!H20 -> 8.27 | E14: ='Study multipliers'!K20 -> 1.2 | F14: ='Study multipliers'!N20*10/D14 -> 0.22046137 | G14: ='Study multipliers'!O20*10/D14 -> 0.46396646 | H14: 1 | I14: =IF(H14=1,1/(G14^2+$R$15),0) -> 4.6454397
B15: POOLED per 10 mg/L | J15: =EXP(S15) -> 1.3589331 | K15: =EXP(S15-1.959964*T15) -> 0.63117527 | L15: =EXP(S15+1.959964*T15) -> 2.9258102 | M15: =IF(AND(N15>1,P15>0),MAX(0,(P15-(N15-1))/P15),0) -> 0 | N15: =SUM($H$13:$H$14) -> 2 | O15: =SUMPRODUCT($H$13:$H$14,1/$G$13:$G$14^2,$F$13:$F$14)/SUMPRODUCT($H$13:$H$14,1/$G$13:$G$14^2) -> 0.30669987 | P15: =IF(N15>1,SUMPRODUCT($H$13:$H$14,1/$G$13:$G$14^2,($F$13:$F$14-O15)^2),0) -> 0.11961702 | Q15: =IF(N15>1,SUMPRODUCT($H$13:$H$14,1/$G$13:$G$14^2)-SUMPRODUCT($H$13:$H$14,1/$G$13:$G$14^2,1/$G$13:$G$14^2)/SUMPRODUCT($H$13:$H$14,1/$G$13:$G$14^2),0) -> 2.6834471 | R15: =IF(Q15>0,MAX(0,(P15-(N15-1))/Q15),0) -> 0 | S15: =SUMPRODUCT($I$13:$I$14,$F$13:$F$14)/SUM($I$13:$I$14) -> 0.30669987 | T15: =SQRT(1/SUM($I$13:$I$14)) -> 0.39126818
A17: Colorectal
A18: Colorectal | B18: Chiu | C18: 2010 | D18: ='Study multipliers'!I27-'Study multipliers'!H27 -> 1 | E18: ='Study multipliers'!K27 -> 1.16 | F18: ='Study multipliers'!N27*10/D18 -> 1.4842001 | G18: ='Study multipliers'!O27*10/D18 -> 0.56925421 | H18: 1 | I18: =IF(H18=1,1/(G18^2+$R$26),0) -> 2.9106698
A19: Colorectal | B19: De Roos | C19: 2003 | D19: ='Study multipliers'!I29-'Study multipliers'!H29 -> 17.69 | E19: ='Study multipliers'!K29 -> 1.2 | F19: ='Study multipliers'!N29*10/D19 -> 0.10306476 | G19: ='Study multipliers'!O29*10/D19 -> 0.10870111 | H19: 1 | I19: =IF(H19=1,1/(G19^2+$R$26),0) -> 31.919199
A20: Colorectal | B20: Espejo-Herrera | C20: 2016 | D20: ='Study multipliers'!I30-'Study multipliers'!H30 -> 5 | E20: ='Study multipliers'!K30 -> 1.52 | F20: ='Study multipliers'!N30*10/D20 -> 0.83742067 | G20: ='Study multipliers'!O30*10/D20 -> 0.20687375 | H20: 1 | I20: =IF(H20=1,1/(G20^2+$R$26),0) -> 16.048807
A21: Colorectal | B21: Jones | C21: 2019 | D21: ='Study multipliers'!I33-'Study multipliers'!H33 -> 13.93 | E21: ='Study multipliers'!K33 -> 0.97 | F21: ='Study multipliers'!N33*10/D21 -> -0.021865906 | G21: ='Study multipliers'!O33*10/D21 -> 0.095009179 | H21: 1 | I21: =IF(H21=1,1/(G21^2+$R$26),0) -> 35.03864
A22: Colorectal | B22: Kuo | C22: 2007 | D22: ='Study multipliers'!I34-'Study multipliers'!H34 -> 6.87 | E22: ='Study multipliers'!K34 -> 1.36 | F22: ='Study multipliers'!N34*10/D22 -> 0.44757598 | G22: ='Study multipliers'!O34*10/D22 -> 0.16846224 | H22: 1 | I22: =IF(H22=1,1/(G22^2+$R$26),0) -> 20.880008
A23: Colorectal | B23: McElroy | C23: 2008 | D23: ='Study multipliers'!I35-'Study multipliers'!H35 -> 42.02 | E23: ='Study multipliers'!K35 -> 1.57 | F23: ='Study multipliers'!N35*10/D23 -> 0.10734784 | G23: ='Study multipliers'!O35*10/D23 -> 0.057961688 | H23: 1 | I23: =IF(H23=1,1/(G23^2+$R$26),0) -> 43.720178
A24: Colorectal | B24: Schullehner | C24: 2018 | D24: ='Study multipliers'!I38-'Study multipliers'!H38 -> 16.06 | E24: ='Study multipliers'!K38 -> 1.14 | F24: ='Study multipliers'!N38*10/D24 -> 0.081586714 | G24: ='Study multipliers'!O38*10/D24 -> 0.023627594 | H24: 1 | I24: =IF(H24=1,1/(G24^2+$R$26),0) -> 49.822036
A25: Colorectal | B25: Yang | C25: 2007 | D25: ='Study multipliers'!I40-'Study multipliers'!H40 -> 1.15 | E25: ='Study multipliers'!K40 -> 0.98 | F25: ='Study multipliers'!N40*10/D25 -> -0.17567572 | G25: ='Study multipliers'!O40*10/D25 -> 0.74258148 | H25: 1 | I25: =IF(H25=1,1/(G25^2+$R$26),0) -> 1.7514962
B26: POOLED per 10 mg/L | J26: =EXP(S26) -> 1.2073464 | K26: =EXP(S26-1.959964*T26) -> 1.051853 | L26: =EXP(S26+1.959964*T26) -> 1.3858261 | M26: =IF(AND(N26>1,P26>0),MAX(0,(P26-(N26-1))/P26),0) -> 0.72259239 | N26: =SUM($H$18:$H$25) -> 8 | O26: =SUMPRODUCT($H$18:$H$25,1/$G$18:$G$25^2,$F$18:$F$25)/SUMPRODUCT($H$18:$H$25,1/$G$18:$G$25^2) -> 0.095405414 | P26: =IF(N26>1,SUMPRODUCT($H$18:$H$25,1/$G$18:$G$25^2,($F$18:$F$25-O26)^2),0) -> 25.233627 | Q26: =IF(N26>1,SUMPRODUCT($H$18:$H$25,1/$G$18:$G$25^2)-SUMPRODUCT($H$18:$H$25,1/$G$18:$G$25^2,1/$G$18:$G$25^2)/SUMPRODUCT($H$18:$H$25,1/$G$18:$G$25^2),0) -> 934.42637 | R26: =IF(Q26>0,MAX(0,(P26-(N26-1))/Q26),0) -> 0.019513177 | S26: =SUMPRODUCT($I$18:$I$25,$F$18:$F$25)/SUM($I$18:$I$25) -> 0.18842493 | T26: =SQRT(1/SUM($I$18:$I$25)) -> 0.070343905
A28: Pancreas
A29: Pancreas | B29: Coss | C29: 2004 | D29: ='Study multipliers'!I45-'Study multipliers'!H45 -> 9.73 | E29: ='Study multipliers'!K45 -> 0.99 | F29: ='Study multipliers'!N45*10/D29 -> -0.010329225 | G29: ='Study multipliers'!O45*10/D29 -> 0.22331728 | H29: 1 | I29: =IF(H29=1,1/(G29^2+$R$32),0) -> 20.05189
A30: Pancreas | B30: Quist | C30: 2018 | D30: ='Study multipliers'!I46-'Study multipliers'!H46 -> 23.08 | E30: ='Study multipliers'!K46 -> 1.18 | F30: ='Study multipliers'!N46*10/D30 -> 0.071713362 | G30: ='Study multipliers'!O46*10/D30 -> 0.1808301 | H30: 1 | I30: =IF(H30=1,1/(G30^2+$R$32),0) -> 30.581485
A31: Pancreas | B31: Yang | C31: 2009 | D31: ='Study multipliers'!I47-'Study multipliers'!H47 -> 6.58 | E31: ='Study multipliers'!K47 -> 1.1 | F31: ='Study multipliers'!N47*10/D31 -> 0.1448483 | G31: ='Study multipliers'!O47*10/D31 -> 0.10849359 | H31: 1 | I31: =IF(H31=1,1/(G31^2+$R$32),0) -> 84.955561
B32: POOLED per 10 mg/L | J32: =EXP(S32) -> 1.1111597 | K32: =EXP(S32-1.959964*T32) -> 0.93902249 | L32: =EXP(S32+1.959964*T32) -> 1.3148523 | M32: =IF(AND(N32>1,P32>0),MAX(0,(P32-(N32-1))/P32),0) -> 0 | N32: =SUM($H$29:$H$31) -> 3 | O32: =SUMPRODUCT($H$29:$H$31,1/$G$29:$G$31^2,$F$29:$F$31)/SUMPRODUCT($H$29:$H$31,1/$G$29:$G$31^2) -> 0.10540424 | P32: =IF(N32>1,SUMPRODUCT($H$29:$H$31,1/$G$29:$G$31^2,($F$29:$F$31-O32)^2),0) -> 0.43546874 | Q32: =IF(N32>1,SUMPRODUCT($H$29:$H$31,1/$G$29:$G$31^2)-SUMPRODUCT($H$29:$H$31,1/$G$29:$G$31^2,1/$G$29:$G$31^2)/SUMPRODUCT($H$29:$H$31,1/$G$29:$G$31^2),0) -> 72.49564 | R32: =IF(Q32>0,MAX(0,(P32-(N32-1))/Q32),0) -> 0 | S32: =SUMPRODUCT($I$29:$I$31,$F$29:$F$31)/SUM($I$29:$I$31) -> 0.10540424 | T32: =SQRT(1/SUM($I$29:$I$31)) -> 0.085879177
A34: Bladder
A35: Bladder | B35: Barry | C35: 2020 | D35: ='Study multipliers'!I53-'Study multipliers'!H53 -> 8.22 | E35: ='Study multipliers'!K53 -> 1.5 | F35: ='Study multipliers'!N53*10/D35 -> 0.49326655 | G35: ='Study multipliers'!O53*10/D35 -> 0.26794534 | H35: 1 | I35: =IF(H35=1,1/(G35^2+$R$41),0) -> 3.2708449
A36: Bladder | B36: Chiu | C36: 2007 | D36: ='Study multipliers'!I54-'Study multipliers'!H54 -> 6.58 | E36: ='Study multipliers'!K54 -> 1.96 | F36: ='Study multipliers'!N54*10/D36 -> 1.022712 | G36: ='Study multipliers'!O54*10/D36 -> 0.25473538 | H36: 1 | I36: =IF(H36=1,1/(G36^2+$R$41),0) -> 3.3464199
A37: Bladder | B37: Espejo-Herrera | C37: 2015 | D37: ='Study multipliers'!I55-'Study multipliers'!H55 -> 22.12 | E37: ='Study multipliers'!K55 -> 1.04 | F37: ='Study multipliers'!N55*10/D37 -> 0.017730883 | G37: ='Study multipliers'!O55*10/D37 -> 0.12734029 | H37: 1 | I37: =IF(H37=1,1/(G37^2+$R$41),0) -> 3.9975655
A38: Bladder | B38: Jones | C38: 2016 | D38: ='Study multipliers'!I56-'Study multipliers'!H56 -> 11.06 | E38: ='Study multipliers'!K56 -> 1.48 | F38: ='Study multipliers'!N56*10/D38 -> 0.35446843 | G38: ='Study multipliers'!O56*10/D38 -> 0.22116562 | H38: 1 | I38: =IF(H38=1,1/(G38^2+$R$41),0) -> 3.5354312
A39: Bladder | B39: Ward | C39: 2003 | D39: ='Study multipliers'!I57-'Study multipliers'!H57 -> 11.02 | E39: ='Study multipliers'!K57 -> 0.5 | F39: ='Study multipliers'!N57*10/D39 -> -0.62899018 | G39: ='Study multipliers'!O57*10/D39 -> 0.16045963 | H39: 1 | I39: =IF(H39=1,1/(G39^2+$R$41),0) -> 3.8508342
A40: Bladder | B40: Zeegers | C40: 2006 | D40: ='Study multipliers'!I59-'Study multipliers'!H59 -> 6.8 | E40: ='Study multipliers'!K59 -> 1.06 | F40: ='Study multipliers'!N59*10/D40 -> 0.085689571 | G40: ='Study multipliers'!O59*10/D40 -> 0.19528211 | H40: 1 | I40: =IF(H40=1,1/(G40^2+$R$41),0) -> 3.6755003
B41: POOLED per 10 mg/L | J41: =EXP(S41) -> 1.2167572 | K41: =EXP(S41-1.959964*T41) -> 0.79869027 | L41: =EXP(S41+1.959964*T41) -> 1.8536574 | M41: =IF(AND(N41>1,P41>0),MAX(0,(P41-(N41-1))/P41),0) -> 0.86565102 | N41: =SUM($H$35:$H$40) -> 6 | O41: =SUMPRODUCT($H$35:$H$40,1/$G$35:$G$40^2,$F$35:$F$40)/SUMPRODUCT($H$35:$H$40,1/$G$35:$G$40^2) -> 0.049792081 | P41: =IF(N41>1,SUMPRODUCT($H$35:$H$40,1/$G$35:$G$40^2,($F$35:$F$40-O41)^2),0) -> 37.216509 | Q41: =IF(N41>1,SUMPRODUCT($H$35:$H$40,1/$G$35:$G$40^2)-SUMPRODUCT($H$35:$H$40,1/$G$35:$G$40^2,1/$G$35:$G$40^2)/SUMPRODUCT($H$35:$H$40,1/$G$35:$G$40^2),0) -> 137.71464 | R41: =IF(Q41>0,MAX(0,(P41-(N41-1))/Q41),0) -> 0.2339367 | S41: =SUMPRODUCT($I$35:$I$40,$F$35:$F$40)/SUM($I$35:$I$40) -> 0.19618931 | T41: =SQRT(1/SUM($I$35:$I$40)) -> 0.21478525
A43: Kidney
A44: Kidney | B44: Jones | C44: 2017 | D44: ='Study multipliers'!I64-'Study multipliers'!H64 -> 9.56 | E44: ='Study multipliers'!K64 -> 2.3 | F44: ='Study multipliers'!N64*10/D44 -> 0.87124385 | G44: ='Study multipliers'!O64*10/D44 -> 0.34057641 | H44: 1 | I44: =IF(H44=1,1/(G44^2+$R$46),0) -> 1.912526
A45: Kidney | B45: Ward | C45: 2007 | D45: ='Study multipliers'!I66-'Study multipliers'!H66 -> 9.56 | E45: ='Study multipliers'!K66 -> 0.89 | F45: ='Study multipliers'!N66*10/D45 -> -0.1218973 | G45: ='Study multipliers'!O66*10/D45 -> 0.23787439 | H45: 1 | I45: =IF(H45=1,1/(G45^2+$R$46),0) -> 2.1576805
B46: POOLED per 10 mg/L | J46: =EXP(S46) -> 1.4116569 | K46: =EXP(S46-1.959964*T46) -> 0.53433658 | L46: =EXP(S46+1.959964*T46) -> 3.7294379 | M46: =IF(AND(N46>1,P46>0),MAX(0,(P46-(N46-1))/P46),0) -> 0.82503155 | N46: =SUM($H$44:$H$45) -> 2 | O46: =SUMPRODUCT($H$44:$H$45,1/$G$44:$G$45^2,$F$44:$F$45)/SUMPRODUCT($H$44:$H$45,1/$G$44:$G$45^2) -> 0.20373289 | P46: =IF(N46>1,SUMPRODUCT($H$44:$H$45,1/$G$44:$G$45^2,($F$44:$F$45-O46)^2),0) -> 5.7153161 | Q46: =IF(N46>1,SUMPRODUCT($H$44:$H$45,1/$G$44:$G$45^2)-SUMPRODUCT($H$44:$H$45,1/$G$44:$G$45^2,1/$G$44:$G$45^2)/SUMPRODUCT($H$44:$H$45,1/$G$44:$G$45^2),0) -> 11.589062 | R46: =IF(Q46>0,MAX(0,(P46-(N46-1))/Q46),0) -> 0.40687641 | S46: =SUMPRODUCT($I$44:$I$45,$F$44:$F$45)/SUM($I$44:$I$45) -> 0.3447641 | T46: =SQRT(1/SUM($I$44:$I$45)) -> 0.49566902
...

Sheet All cancers pooled
A1: Pooling every cancer site together - a demonstration, not an estimate
A2: This sheet computes what the question 'what is the overall multiplier for nitrate and cancer' produces if you take it literally. The answer should not be used as a risk estimate for any purpose. Pooling across biologically unrelated cancer sites assumes a single common effect of nitrate on all cancers, which no review in this literature claims and which the site-by-site results contradict. It is the same structural move that makes the Temkin et al. attributable-burden calculation unreliable. It is computed here so that the number is on the record with its caveats attached, rather than being produced later without them.
A4: Variant | B4: What it pools | C4: k | D4: Pooled multiplier | E4: 95% LCL | F4: 95% UCL | G4: I^2
A5: A. Every study-site estimate, as published | B5: All cohort and case-control estimates, counting repeat appearances of the same cohort at different sites | C5: =I5 -> 64 | D5: =EXP(N5) -> 1.1199189 | E5: =EXP(N5-1.959964*O5) -> 1.0627045 | F5: =EXP(N5+1.959964*O5) -> 1.1802137 | G5: =MAX(0,(K5-(I5-1))/K5) -> 0.50516851 | I5: 64 | J5: =SUMPRODUCT(1/$B$200:$B$263^2,$A$200:$A$263)/SUMPRODUCT(1/$B$200:$B$263^2) -> 0.1135721 | K5: =SUMPRODUCT(1/$B$200:$B$263^2,($A$200:$A$263-J5)^2) -> 127.31607 | L5: =SUMPRODUCT(1/$B$200:$B$263^2)-SUMPRODUCT(1/$B$200:$B$263^2,1/$B$200:$B$263^2)/SUMPRODUCT(1/$B$200:$B$263^2) -> 4575.9003 | M5: =MAX(0,(K5-(I5-1))/L5) -> 0.014055391 | N5: =SUMPRODUCT(1/($B$200:$B$263^2+M5),$A$200:$A$263)/SUMPRODUCT(1/($B$200:$B$263^2+M5)) -> 0.1132563 | O5: =SQRT(1/SUMPRODUCT(1/($B$200:$B$263^2+M5))) -> 0.026755201
A6: B. De-duplicated study-site estimates | B6: One estimate per independent population per cancer site | C6: =I6 -> 57 | D6: =EXP(N6) -> 1.1215274 | E6: =EXP(N6-1.959964*O6) -> 1.0594051 | F6: =EXP(N6+1.959964*O6) -> 1.1872925 | G6: =MAX(0,(K6-(I6-1))/K6) -> 0.50523412 | I6: 57 | J6: =SUMPRODUCT(1/$B$320:$B$376^2,$A$320:$A$376)/SUMPRODUCT(1/$B$320:$B$376^2) -> 0.12194975 | K6: =SUMPRODUCT(1/$B$320:$B$376^2,($A$320:$A$376-J6)^2) -> 113.18485 | L6: =SUMPRODUCT(1/$B$320:$B$376^2)-SUMPRODUCT(1/$B$320:$B$376^2,1/$B$320:$B$376^2)/SUMPRODUCT(1/$B$320:$B$376^2) -> 3744.0473 | M6: =MAX(0,(K6-(I6-1))/L6) -> 0.015273537 | N6: =SUMPRODUCT(1/($B$320:$B$376^2+M6),$A$320:$A$376)/SUMPRODUCT(1/($B$320:$B$376^2+M6)) -> 0.11469149 | O6: =SQRT(1/SUMPRODUCT(1/($B$320:$B$376^2+M6))) -> 0.029073999
A7: C. Pool of the site-level pooled estimates | B7: Each cancer site contributes once, using its de-duplicated pooled multiplier | C7: =I7 -> 18 | D7: =EXP(N7) -> 1.1052537 | E7: =EXP(N7-1.959964*O7) -> 1.0327519 | F7: =EXP(N7+1.959964*O7) -> 1.1828453 | G7: =MAX(0,(K7-(I7-1))/K7) -> 0.38322387 | I7: =SUMPRODUCT(--($B$400:$B$419<>"")) -> 18 | J7: =SUMPRODUCT(IF($B$400:$B$419="",0,1/$B$400:$B$419^2),IF($A$400:$A$419="",0,$A$400:$A$419))/SUMPRODUCT(IF($B$400:$B$419="",0,1/$B$400:$B$419^2)) -> 0.11996932 | K7: =SUMPRODUCT(IF($B$400:$B$419="",0,1/$B$400:$B$419^2),(IF($A$400:$A$419="",0,$A$400:$A$419)-J7)^2) -> 27.562675 | L7: =SUMPRODUCT(IF($B$400:$B$419="",0,1/$B$400:$B$419^2))-SUMPRODUCT(IF($B$400:$B$419="",0,1/$B$400:$B$419^2),IF($B$400:$B$419="",0,1/$B$400:$B$419^2))/SUMPRODUCT(IF($B$400:$B$419="",0,1/$B$400:$B$419^2)) -> 1912.9157 | M7: =MAX(0,(K7-(I7-1))/L7) -> 0.005521767 | N7: =SUMPRODUCT(IF($B$400:$B$419="",0,1/($B$400:$B$419^2+M7)),IF($A$400:$A$419="",0,$A$400:$A$419))/SUMPRODUCT(IF($B$400:$B$419="",0,1/($B$400:$B$419^2+M7))) -> 0.10007488 | O7: =SQRT(1/SUMPRODUCT(IF($B$400:$B$419="",0,1/($B$400:$B$419^2+M7)))) -> 0.034616925
A9: How to read this: all three variants land near 1.1, with heterogeneity around 50%. An I-squared of 50% across sites means half the variation between these estimates is real difference between cancers, not sampling noise - which is the statistical way of saying a single all-cancer multiplier is not a meaningful quantity. Note also that de-duplicating barely moves the all-cancer figure, because the Iowa Women's Health Study estimates it removes sit on both sides of 1.0.
A198: Helper ranges below - ln(multiplier) and SE pulled from the 'Study multipliers' sheet
A200: ='Study multipliers'!N4 -> 0.14842001 | B200: ='Study multipliers'!O4 -> 0.052514244
A201: ='Study multipliers'!N7 -> 0.40546511 | B201: ='Study multipliers'!O7 -> 1.2817655
A202: ='Study multipliers'!N8 -> 0.18232156 | B202: ='Study multipliers'!O8 -> 0.064656519
A203: ='Study multipliers'!N9 -> 0.019802627 | B203: ='Study multipliers'!O9 -> 0.25429793
A204: ='Study multipliers'!N10 -> -0.12783337 | B204: ='Study multipliers'!O10 -> 0.20542839
A205: ='Study multipliers'!N11 -> 0.18232156 | B205: ='Study multipliers'!O11 -> 0.43021172
A206: ='Study multipliers'!N12 -> 0.019802627 | B206: ='Study multipliers'!O12 -> 0.045136214
A207: ='Study multipliers'!N13 -> 0.13102826 | B207: ='Study multipliers'!O13 -> 0.046919953
A208: ='Study multipliers'!N19 -> 0.048790164 | B208: ='Study multipliers'!O19 -> 0.068435947
A209: ='Study multipliers'!N20 -> 0.18232156 | B209: ='Study multipliers'!O20 -> 0.38370026
A210: ='Study multipliers'!N26 -> 0.13976194 | B210: ='Study multipliers'!O26 -> 0.068287327
A211: ='Study multipliers'!N27 -> 0.14842001 | B211: ='Study multipliers'!O27 -> 0.056925421
A212: ='Study multipliers'!N28 -> 0.14842001 | B212: ='Study multipliers'!O28 -> 0.056925421
A213: ='Study multipliers'!N29 -> 0.18232156 | B213: ='Study multipliers'!O29 -> 0.19229226
A214: ='Study multipliers'!N30 -> 0.41871033 | B214: ='Study multipliers'!O30 -> 0.10343688
A215: ='Study multipliers'!N31 -> 1.0367369 | B215: ='Study multipliers'!O31 -> 0.4919691
A216: ='Study multipliers'!N33 -> -0.030459207 | B216: ='Study multipliers'!O33 -> 0.13234779
A217: ='Study multipliers'!N34 -> 0.3074847 | B217: ='Study multipliers'!O34 -> 0.11573356
A218: ='Study multipliers'!N35 -> 0.45107562 | B218: ='Study multipliers'!O35 -> 0.24355501
A219: ='Study multipliers'!N38 -> 0.13102826 | B219: ='Study multipliers'!O38 -> 0.037945917
A220: ='Study multipliers'!N39 -> 0.0099503309 | B220: ='Study multipliers'!O39 -> 0.19100275
A221: ='Study multipliers'!N40 -> -0.020202707 | B221: ='Study multipliers'!O40 -> 0.08539687
A222: ='Study multipliers'!N45 -> -0.010050336 | B222: ='Study multipliers'!O45 -> 0.21728772
A223: ='Study multipliers'!N46 -> 0.16551444 | B223: ='Study multipliers'!O46 -> 0.41735586
A224: ='Study multipliers'!N47 -> 0.09531018 | B224: ='Study multipliers'!O47 -> 0.071388784
A225: ='Study multipliers'!N48 -> -0.65392647 | B225: ='Study multipliers'!O48 -> 0.43699236
A226: ='Study multipliers'!N53 -> 0.40546511 | B226: ='Study multipliers'!O53 -> 0.22025107
A227: ='Study multipliers'!N54 -> 0.67294447 | B227: ='Study multipliers'!O54 -> 0.16761588
A228: ='Study multipliers'!N55 -> 0.039220713 | B228: ='Study multipliers'!O55 -> 0.28167672
A229: ='Study multipliers'!N56 -> 0.39204209 | B229: ='Study multipliers'!O56 -> 0.24460917
A230: ='Study multipliers'!N57 -> -0.69314718 | B230: ='Study multipliers'!O57 -> 0.17682651
A231: ='Study multipliers'!N58 -> 0.88789126 | B231: ='Study multipliers'!O58 -> 0.44939765
...

Sheet Iowa attributable fraction
A1: What these multipliers imply for Iowa
A2: Population attributable fraction = Pe x (RR - 1) / (1 + Pe x (RR - 1)), where Pe is the share of Iowans exposed above the reference level. Pe is an input - change the yellow cell. Iowa case counts are 2023 incidence from the uploaded SEER/USCS extract (3-ewg.xlsx).
A4: Exposed fraction of Iowa population (Pe) | B4: 0.1 | C4: Editable. 10% is a placeholder. For reference: 18% of Iowans are on private wells, and EWG's own model put 8% of those above 5 mg/L.
A6: Cancer site | B6: Iowa cases, 2023 | C6: Pooled multiplier (de-dup, high vs low) | D6: Attributable fraction | E6: Attributable cases | F6: Multiplier per 10 mg/L | G6: Attributable fraction (per 10) | H6: Attributable cases (per 10)
A7: Colorectal | B7: 1488 | C7: ='Study multipliers'!K42 -> 1.1838201 | D7: =IF(C7>1,$B$4*(C7-1)/(1+$B$4*(C7-1)),0) -> 0.018050208 | E7: =D7*B7 -> 26.858709 | F7: ='Per 10 mg per L'!J26 -> 1.2073464 | G7: =IF(F7>1,$B$4*(F7-1)/(1+$B$4*(F7-1)),0) -> 0.020313453 | H7: =G7*B7 -> 30.226418
A8: Stomach | B8: 194 | C8: ='Study multipliers'!K15 -> 1.1516183 | D8: =IF(C8>1,$B$4*(C8-1)/(1+$B$4*(C8-1)),0) -> 0.014935385 | E8: =D8*B8 -> 2.8974647 | F8: ='Per 10 mg per L'!J10 -> 1.3010673 | G8: =IF(F8>1,$B$4*(F8-1)/(1+$B$4*(F8-1)),0) -> 0.02922681 | H8: =G8*B8 -> 5.6700012
A9: Ovary | B9: 205 | C9: ='Study multipliers'!K116 -> 2.14 | D9: =IF(C9>1,$B$4*(C9-1)/(1+$B$4*(C9-1)),0) -> 0.10233393 | E9: =D9*B9 -> 20.978456 | F9: ='Per 10 mg per L'!J75 -> 1.9858136 | G9: =IF(F9>1,$B$4*(F9-1)/(1+$B$4*(F9-1)),0) -> 0.089735147 | H9: =G9*B9 -> 18.395705
A10: Thyroid | B10: 477 | C10: ='Study multipliers'!K132 -> 2.18 | D10: =IF(C10>1,$B$4*(C10-1)/(1+$B$4*(C10-1)),0) -> 0.10554562 | E10: =D10*B10 -> 50.345259 | F10: ='Per 10 mg per L'!J83 -> 2.3137874 | G10: =IF(F10>1,$B$4*(F10-1)/(1+$B$4*(F10-1)),0) -> 0.11612269 | H10: =G10*B10 -> 55.390523
A11: Kidney | B11: 879 | C11: ='Study multipliers'!K69 -> 1.2242959 | D11: =IF(C11>1,$B$4*(C11-1)/(1+$B$4*(C11-1)),0) -> 0.021937543 | E11: =D11*B11 -> 19.2831 | F11: ='Per 10 mg per L'!J46 -> 1.4116569 | G11: =IF(F11>1,$B$4*(F11-1)/(1+$B$4*(F11-1)),0) -> 0.039538075 | H11: =G11*B11 -> 34.753968
A12: Bladder | B12: 815 | C12: ='Study multipliers'!K61 -> 1.1523387 | D12: =IF(C12>1,$B$4*(C12-1)/(1+$B$4*(C12-1)),0) -> 0.015005286 | E12: =D12*B12 -> 12.229308 | F12: ='Per 10 mg per L'!J41 -> 1.2167572 | G12: =IF(F12>1,$B$4*(F12-1)/(1+$B$4*(F12-1)),0) -> 0.021215853 | H12: =G12*B12 -> 17.290921
A13: TOTAL across the six nitrate-associated sites | B13: =SUM(B7:B12) -> 4058 | E13: =SUM(E7:E12) -> 132.5923 | H13: =SUM(H7:H12) -> 161.72754
A15: All Iowa cancer cases, 2023 | B15: 21258
A16: Attributable share of ALL Iowa cancers (high vs low scale) | B16: =E13/B15 -> 0.0062372894
A17: For comparison: EWG's own state estimate for Iowa | B17: 74 to 335 cases, i.e. 0.35% to 1.57% of all Iowa cancers
A19: This is an illustration of scale, not an attributable-burden estimate. It inherits every weakness of the underlying multipliers: a highest-versus-lowest contrast that means a different dose in every study, pooled estimates with substantial heterogeneity, and no adjustment for the fact that these are observational associations rather than demonstrated causal effects.
A20: It is shown because it lands in the same place the EWG figure does, by a completely different route and without assuming causation: even taking the associations at face value, the implied share of Iowa's cancer burden is low single-digit percent at most.
A21: Iowa case counts: colorectal, thyroid, kidney, bladder and stomach are non-Hispanic White population counts; ovary is the female population count. Totals are therefore conservative relative to all-race counts.
